Workbook
Name Anzahl: #REF!
Name AnzahlKlassenHistogramm: #REF!
Name BEOBPOGW: #REF!
Name BEOBPPM: #REF!
Name BEOBPUGW: #REF!
Name BERP: #REF!
Name BERPOGW: #REF!
Name BERPUGW: #REF!
Name BG: #REF!
Name CP: #REF!
Name CPK: #REF!
Name CPO: #REF!
Name CPU: #REF!
Name Datum: #REF!
Name Häufigkeitsdichte: #REF!
Name Maßeinheit: #REF!
Name Maximum: #REF!
Name Median: #REF!
Name Merkmal: #REF!
Name Merkman: #REF!
Name Minimum: #REF!
Name Mittelwert: #REF!
Name Normalverteilung_S: #REF!
Name OGW: #REF!
Name P: #REF!
Name POGW: #REF!
Name PUGW: #REF!
Name Sollwert: #REF!
Name Spannweite: #REF!
Name Standardabweichung: #REF!
Name UGW: #REF!
Name xi: #REF!

Sheet D
N1: Weight | O1: WEIGHT | P1: Peak 1 | Q1: Peak 2 | R1: Peak 3 | S1: Peak 4 | T1: Peak 5 | U1: Peak 6 | V1: Peak 7 | Y1: Root 1 | Z1: Root 2 | AA1: Root 3 | AB1: Root 4 | AC1: Root 5 | AD1: Root 6 | AH1: THKC | AJ1: THKF | AQ1: THKF | AR1: =AVERAGE(AQ2:AQ126) -> 1.4406
M2: 1 | N2: 93.057 | O2: 93.057 | P2: 1.33 | Q2: 1.32 | R2: 1.33 | S2: 1.38 | T2: 0.97 | U2: 1.21 | V2: 1.31 | W2: 0.007 | Y2: 1.2 | Z2: 1.22 | AA2: 1.24 | AB2: 1.16 | AC2: 1.21 | AD2: 1.17 | AH2: 1.95 | AJ2: 1.44 | AP2: 1 | AQ2: 1.44 | AR2: =AR1 -> 1.4406 | AS2: =AQ2-AR2 -> -0.0006 | AV2: 20 | BN2: 1014.6 | BO2: 26.936261 | BP2: 27.065 | BQ2: 35.570923 | BR2: 35.643216
B3: Número de parte | C3: 10433939 | M3: 2 | N3: 92.787 | O3: 93.003 | P3: 1.28 | Q3: 1.4 | R3: 1.29 | S3: 1.34 | T3: 0.98 | U3: 1.16 | V3: 1.32 | W3: 0.007 | Y3: 1.19 | Z3: 1.26 | AA3: 1.27 | AB3: 1.12 | AC3: 1.2 | AD3: 1.16 | AH3: 1.96 | AJ3: 1.43 | AP3: 2 | AQ3: 1.43 | AR3: =AR2 -> 1.4406 | AS3: =AQ3-AR3 -> -0.0106 | AV3: 21 | AZ3: μ | BA3: σ | BB3: Ppk PpU PpL | BC3: Pp | BD3: Cpk CpU CpL | BE3: Cp | BN3: 1017.1 | BO3: 26.999304 | BP3: 27.048 | BQ3: 35.530923 | BR3: 35.693412
B4: Descripción | M4: 3 | N4: 93.192 | O4: 93.192 | P4: 1.3 | Q4: 1.35 | R4: 1.32 | S4: 1.37 | T4: 1 | U4: 1.22 | V4: 1.34 | W4: 0.002 | Y4: 1.21 | Z4: 1.23 | AA4: 1.25 | AB4: 1.14 | AC4: 1.23 | AD4: 1.18 | AH4: 1.95 | AJ4: 1.46 | AP4: 3 | AQ4: 1.44 | AR4: =AR3 -> 1.4406 | AS4: =AQ4-AR4 -> -0.0006 | AV4: 22 | AZ4: ='[1] PEAK 1'!P31 -> 1.28784 | BA4: ='[1] PEAK 1'!P32 -> 0.024938117 | BB4: ='[1] PEAK 1'!P42 -> 1.976 | BC4: ='[1] PEAK 1'!P41 -> 2.005 | BD4: ='[1] PEAK 1'!P37 -> 1.878 | BE4: ='[1] PEAK 1'!P36 -> 1.905 | BN4: 1014.3 | BO4: 26.983652 | BP4: 27.0205 | BQ4: 35.444769 | BR4: 35.677725
B5: Material | C5: PB420B | M5: 4 | N5: 93.055 | O5: 93.055 | P5: 1.28 | Q5: 1.37 | R5: 1.27 | S5: 1.31 | T5: 1.04 | U5: 1.22 | V5: 1.33 | W5: 0.005 | Y5: 1.22 | Z5: 1.2 | AA5: 1.25 | AB5: 1.1 | AC5: 1.19 | AD5: 1.17 | AH5: 1.96 | AJ5: 1.45 | AP5: 4 | AQ5: 1.42 | AR5: =AR4 -> 1.4406 | AS5: =AQ5-AR5 -> -0.0206 | AV5: 23 | AZ5: ='[1]PEAK 2'!P31 -> 1.35208 | BA5: ='[1]PEAK 2'!P32 -> 0.024993418 | BB5: ='[1]PEAK 2'!P42 -> 1.895 | BC5: ='[1]PEAK 2'!P41 -> 2.001 | BD5: ='[1]PEAK 2'!P37 -> 1.758 | BE5: ='[1]PEAK 2'!P36 -> 1.856 | BN5: 1015.4 | BO5: 26.926261 | BP5: 27.01725 | BQ5: 35.547462 | BR5: 35.682431
A6: Fecha | B6: rev. PFD | C6: 45937 | M6: 5 | N6: 93.13 | O6: 93.13 | P6: 1.3 | Q6: 1.34 | R6: 1.33 | S6: 1.35 | T6: 1 | U6: 1.18 | V6: 1.3 | W6: 0.001 | Y6: 1.19 | Z6: 1.26 | AA6: 1.3 | AB6: 1.12 | AC6: 1.23 | AD6: 1.14 | AH6: 1.95 | AJ6: 1.43 | AP6: 5 | AQ6: 1.43 | AR6: =AR5 -> 1.4406 | AS6: =AQ6-AR6 -> -0.0106 | AV6: 24 | AZ6: ='[1]PEAK 3'!P31 -> 1.30232 | BA6: ='[1]PEAK 3'!P32 -> 0.024134569 | BB6: ='[1]PEAK 3'!P42 -> 1.902 | BC6: ='[1]PEAK 3'!P41 -> 2.072 | BD6: ='[1]PEAK 3'!P37 -> 1.834 | BE6: ='[1]PEAK 3'!P36 -> 1.998 | BN6: 1017.2 | BO6: 26.981478 | BP6: 26.99 | BQ6: 35.514 | BR6: 35.703804
B7: No. de parte cliente/kunhwa | C7: 10433939 / 14DAJ9000 | E7: ( | F7: / | M7: 6 | N7: 92.666 | O7: 93.006 | P7: 1.26 | Q7: 1.37 | R7: 1.28 | S7: 1.36 | T7: 0.98 | U7: 1.21 | V7: 1.32 | W7: 0.006 | Y7: 1.21 | Z7: 1.24 | AA7: 1.29 | AB7: 1.15 | AC7: 1.17 | AD7: 1.14 | AH7: 1.95 | AJ7: 1.43 | AP7: 6 | AQ7: 1.43 | AR7: =AR6 -> 1.4406 | AS7: =AQ7-AR7 -> -0.0106 | AV7: 25 | AZ7: ='[1]PEAK 4'!P31 -> 1.33496 | BA7: ='[1]PEAK 4'!P32 -> 0.02632379 | BB7: ='[1]PEAK 4'!P42 -> 1.709 | BC7: ='[1]PEAK 4'!P41 -> 1.899 | BD7: ='[1]PEAK 4'!P37 -> 1.692 | BE7: ='[1]PEAK 4'!P36 -> 1.88 | BN7: 1017.4769 | BO7: 26.901043 | BP7: 27.054 | BQ7: 35.562846 | BR7: 35.65498
C8: 14DAJ9000 | M8: 7 | N8: 93.154 | O8: 93.154 | P8: 1.25 | Q8: 1.37 | R8: 1.32 | S8: 1.32 | T8: 1.02 | U8: 1.18 | V8: 1.36 | W8: 0.004 | Y8: 1.2 | Z8: 1.23 | AA8: 1.27 | AB8: 1.11 | AC8: 1.18 | AD8: 1.17 | AH8: 1.97 | AJ8: 1.45 | AP8: 7 | AQ8: 1.45 | AR8: =AR7 -> 1.4406 | AS8: =AQ8-AR8 -> 0.0094 | AV8: 26 | AZ8: ='[1]PEAK 5'!P31 -> 0.99632 | BA8: ='[1]PEAK 5'!P32 -> 0.022235398 | BB8: ='[1]PEAK 5'!P42 -> 1.894 | BC8: ='[1]PEAK 5'!P41 -> 2.249 | BD8: ='[1]PEAK 5'!P37 -> 1.781 | BE8: ='[1]PEAK 5'!P36 -> 2.115 | BN8: 1016.6808 | BO8: 26.928435 | BP8: 27.034 | BQ8: 35.618615 | BR8: 35.679882
B9: Nombre de la parte | C9: BOOT UFi4600 / UF3-51 | M9: 8 | N9: 92.905 | O9: 92.905 | P9: 1.33 | Q9: 1.35 | R9: 1.29 | S9: 1.33 | T9: 1.01 | U9: 1.22 | V9: 1.3 | W9: 0.005 | Y9: 1.17 | Z9: 1.22 | AA9: 1.3 | AB9: 1.13 | AC9: 1.25 | AD9: 1.14 | AH9: 1.95 | AJ9: 1.45 | AP9: 8 | AQ9: 1.42 | AR9: =AR8 -> 1.4406 | AS9: =AQ9-AR9 -> -0.0206 | AV9: 27 | AZ9: ='[1]PEAK 6'!P31 -> 1.20496 | BA9: ='[1]PEAK 6'!P32 -> 0.026688889 | BB9: ='[1]PEAK 6'!P42 -> 1.81 | BC9: ='[1]PEAK 6'!P41 -> 1.873 | BD9: ='[1]PEAK 6'!P37 -> 1.782 | BE9: ='[1]PEAK 6'!P36 -> 1.844 | BN9: 1015.0337 | BO9: 26.966261 | BP9: 27.04 | BQ9: 35.604769 | BR9: 35.708314
B10: Modelo | C10: GM T1XX | M10: 9 | N10: 92.94 | O10: 92.94 | P10: 1.31 | Q10: 1.38 | R10: 1.31 | S10: 1.38 | T10: 0.97 | U10: 1.17 | V10: 1.3 | W10: 0.001 | Y10: 1.2 | Z10: 1.25 | AA10: 1.26 | AB10: 1.13 | AC10: 1.19 | AD10: 1.17 | AH10: 1.96 | AJ10: 1.48 | AP10: 9 | AQ10: 1.48 | AR10: =AR9 -> 1.4406 | AS10: =AQ10-AR10 -> 0.0394 | AV10: 28 | AZ10: ='[1]PEAK 7'!P31 -> 1.33824 | BA10: ='[1]PEAK 7'!P32 -> 0.030771373 | BB10: ='[1]PEAK 7'!P42 -> 1.822 | BC10: ='[1]PEAK 7'!P41 -> 2.167 | BD10: ='[1]PEAK 7'!P37 -> 1.754 | BE10: ='[1]PEAK 7'!P36 -> 2.085 | BN10: 1017.6141 | BO10: 27.063652 | BP10: 27.06725 | BQ10: 35.554 | BR10: 35.701255
B11: Dibujo del cliente | C11: 3100918563 | M11: 10 | N11: 93.156 | O11: 93.156 | P11: 1.28 | Q11: 1.38 | R11: 1.3 | S11: 1.31 | T11: 1.01 | U11: 1.19 | V11: 1.37 | W11: 0.006 | Y11: 1.19 | Z11: 1.22 | AA11: 1.31 | AB11: 1.14 | AC11: 1.22 | AD11: 1.12 | AH11: 1.96 | AJ11: 1.45 | AP11: 10 | AQ11: 1.42 | AR11: =AR10 -> 1.4406 | AS11: =AQ11-AR11 -> -0.0206 | AV11: 29 | AZ11: ='[1]PEAK 8'!P31 -> 0.005152 | BA11: ='[1]PEAK 8'!P32 -> 0.0029677188 | BB11: ='[1]PEAK 8'!P42 -> -0.579 | BC11: ='[1]PEAK 8'!P41 -> 0 | BD11: ='[1]PEAK 8'!P37 -> -0.571 | BE11: ='[1]PEAK 8'!P36 -> 0 | BN11: 1016.9416 | BO11: 27.018435 | BP11: 27.005 | BQ11: 35.537077 | BR11: 35.675373
B12: Peso | C12: 0.0929575 | M12: 11 | N12: 92.972 | O12: 92.972 | P12: 1.29 | Q12: 1.31 | R12: 1.32 | S12: 1.34 | T12: 0.99 | U12: 1.26 | V12: 1.32 | W12: 0.002 | Y12: 1.21 | Z12: 1.26 | AA12: 1.24 | AB12: 1.12 | AC12: 1.23 | AD12: 1.16 | AH12: 1.95 | AJ12: 1.46 | AP12: 11 | AQ12: 1.46 | AR12: =AR11 -> 1.4406 | AS12: =AQ12-AR12 -> 0.0194 | AV12: 30 | AZ12: ='[1]PEAK 9'!P31 -> 0 | BA12: ='[1]PEAK 9'!P32 -> 0 | BB12: ='[1]PEAK 9'!P42 -> #DIV/0! | BC12: ='[1]PEAK 9'!P41 -> #DIV/0! | BD12: ='[1]PEAK 9'!P37 -> #DIV/0! | BE12: ='[1]PEAK 9'!P36 -> #DIV/0! | BN12: 1020.0024 | BO12: 26.933217 | BP12: 27.0165 | BQ12: 35.562077 | BR12: 35.666745
B13: Eng. Change level | C13: A | M13: 12 | N13: 93.15 | O13: 93.15 | P13: 1.33 | Q13: 1.35 | R13: 1.3 | S13: 1.32 | T13: 1.02 | U13: 1.2 | V13: 1.35 | W13: 0.001 | Y13: 1.18 | Z13: 1.21 | AA13: 1.31 | AB13: 1.12 | AC13: 1.24 | AD13: 1.16 | AH13: 1.96 | AJ13: 1.439 | AP13: 12 | AQ13: 1.439 | AR13: =AR12 -> 1.4406 | AS13: =AQ13-AR13 -> -0.0016 | AV13: 31 | AZ13: ='[1]ROOT 1'!P31 -> 1.19464 | BA13: ='[1]ROOT 1'!P32 -> 0.019860156 | BB13: ='[1]ROOT 1'!P42 -> 1.768 | BC13: ='[1]ROOT 1'!P41 -> 2.518 | BD13: ='[1]ROOT 1'!P37 -> 1.727 | BE13: ='[1]ROOT 1'!P36 -> 2.459 | BN13: 1017.4357 | BO13: 26.929304 | BP13: 27.03225 | BQ13: 35.583231 | BR13: 35.693412
B14: Date | C14: 43384 | M14: 13 | N14: 92.833 | O14: 93.003 | P14: 1.28 | Q14: 1.37 | R14: 1.27 | S14: 1.34 | T14: 1.01 | U14: 1.25 | V14: 1.29 | W14: 0.003 | Y14: 1.21 | Z14: 1.25 | AA14: 1.27 | AB14: 1.15 | AC14: 1.18 | AD14: 1.19 | AH14: 1.96 | AJ14: 1.46 | AP14: 13 | AQ14: 1.46 | AR14: =AR13 -> 1.4406 | AS14: =AQ14-AR14 -> 0.0194 | AV14: 32 | AZ14: ='[1]ROOT 2'!P31 -> 1.22576 | BA14: ='[1]ROOT 2'!P32 -> 0.022370199 | BB14: ='[1]ROOT 2'!P42 -> 2.023 | BC14: ='[1]ROOT 2'!P41 -> 2.235 | BD14: ='[1]ROOT 2'!P37 -> 1.972 | BE14: ='[1]ROOT 2'!P36 -> 2.179 | BN14: 1016.6808 | BO14: 26.919304 | BP14: 27.054 | BQ14: 35.598231 | BR14: 35.69851
B15: IMDS | C15: IMDS 1446951989 / 2 | M15: 14 | N15: 93.184 | O15: 93.184 | P15: 1.29 | Q15: 1.38 | R15: 1.32 | S15: 1.29 | T15: 0.99 | U15: 1.18 | V15: 1.32 | W15: 0.004 | Y15: 1.16 | Z15: 1.25 | AA15: 1.3 | AB15: 1.12 | AC15: 1.22 | AD15: 1.14 | AH15: 1.95 | AJ15: 1.42 | AP15: 14 | AQ15: 1.42 | AR15: =AR14 -> 1.4406 | AS15: =AQ15-AR15 -> -0.0206 | AV15: 33 | AZ15: ='[1]ROOT 3'!P31 -> 1.27528 | BA15: ='[1]ROOT 3'!P32 -> 0.02164881 | BB15: ='[1]ROOT 3'!P42 -> 1.929 | BC15: ='[1]ROOT 3'!P41 -> 2.31 | BD15: ='[1]ROOT 3'!P37 -> 1.793 | BE15: ='[1]ROOT 3'!P36 -> 2.147 | BN15: 1016.1455 | BO15: 26.959304 | BP15: 27.11 | BQ15: 35.557462 | BR15: 35.681059
B16: Customer name division | C16: GKN VLG (Celaya) | M16: 15 | N16: 92.908 | O16: 92.908 | P16: 1.3 | Q16: 1.34 | R16: 1.26 | S16: 1.29 | T16: 1.01 | U16: 1.26 | V16: 1.3 | W16: 0.008 | Y16: 1.2 | Z16: 1.26 | AA16: 1.28 | AB16: 1.18 | AC16: 1.19 | AD16: 1.16 | AH16: 1.95 | AJ16: 1.438 | AP16: 15 | AQ16: 1.438 | AR16: =AR15 -> 1.4406 | AS16: =AQ16-AR16 -> -0.0026 | AV16: 34 | AZ16: ='[1]ROOT 4'!P31 -> 1.14016 | BA16: ='[1]ROOT 4'!P32 -> 0.024853896 | BB16: ='[1]ROOT 4'!P42 -> 2.01 | BC16: ='[1]ROOT 4'!P41 -> 2.012 | BD16: ='[1]ROOT 4'!P37 -> 1.996 | BE16: ='[1]ROOT 4'!P36 -> 1.998 | BN16: 1017.6004 | BO16: 27.011478 | BP16: 27.039 | BQ16: 35.598231 | BR16: 35.676549
B17: Purchase order | C17: 3597 | M17: 16 | N17: 93.049 | O17: 93.049 | P17: 1.26 | Q17: 1.39 | R17: 1.32 | S17: 1.35 | T17: 1.03 | U17: 1.21 | V17: 1.35 | W17: 0.009 | Y17: 1.2 | Z17: 1.19 | AA17: 1.27 | AB17: 1.13 | AC17: 1.19 | AD17: 1.13 | AH17: 1.94 | AJ17: 1.45 | AP17: 16 | AQ17: 1.45 | AR17: =AR16 -> 1.4406 | AS17: =AQ17-AR17 -> 0.0094 | AV17: 35 | AZ17: ='[1]ROOT 5'!P31 -> 1.2116 | BA17: ='[1]ROOT 5'!P32 -> 0.024143389 | BB17: ='[1]ROOT 5'!P42 -> 1.773 | BC17: ='[1]ROOT 5'!P41 -> 2.071 | BD17: ='[1]ROOT 5'!P37 -> 1.722 | BE17: ='[1]ROOT 5'!P36 -> 2.012 | BN17: 1016.1455 | BO17: 26.929739 | BP17: 26.96 | BQ17: 35.606308 | BR17: 35.716941
B18: Humedad de resina | C18: <0.05% | M18: 17 | N18: 92.9 | O18: 92.9 | P18: 1.32 | Q18: 1.36 | R18: 1.3 | S18: 1.33 | T18: 0.98 | U18: 1.24 | V18: 1.36 | W18: 0.001 | Y18: 1.19 | Z18: 1.25 | AA18: 1.31 | AB18: 1.15 | AC18: 1.23 | AD18: 1.15 | AH18: 1.95 | AJ18: 1.44 | AP18: 17 | AQ18: 1.46 | AR18: =AR17 -> 1.4406 | AS18: =AQ18-AR18 -> 0.0194 | AV18: 36 | AZ18: ='[1]ROOT 6'!P31 -> 1.16912 | BA18: ='[1]ROOT 6'!P32 -> 0.028709221 | BB18: ='[1]ROOT 6'!P42 -> 1.964 | BC18: ='[1]ROOT 6'!P41 -> 2.322 | BD18: ='[1]ROOT 6'!P37 -> 1.99 | BE18: ='[1]ROOT 6'!P36 -> 2.353 | BN18: 1017.3259 | BO18: 26.951043 | BP18: 27.02675 | BQ18: 35.602846 | BR18: 35.67851
B19: Temperatura de secado | C19: 100℃ ± 10℃ | M19: 18 | N19: 93.269 | O19: 93.269 | P19: 1.3 | Q19: 1.35 | R19: 1.27 | S19: 1.33 | T19: 1.02 | U19: 1.19 | V19: 1.29 | W19: 0.009 | Y19: 1.21 | Z19: 1.25 | AA19: 1.27 | AB19: 1.1 | AC19: 1.2 | AD19: 1.18 | AH19: 1.97 | AJ19: 1.46 | AP19: 18 | AQ19: 1.46 | AR19: =AR18 -> 1.4406 | AS19: =AQ19-AR19 -> 0.0194 | AV19: 37 | AZ19: ='[1]ROOT 7'!P31 -> 0 | BA19: ='[1]ROOT 7'!P32 -> 0 | BB19: ='[1]ROOT 7'!P42 -> #DIV/0! | BC19: ='[1]ROOT 7'!P41 -> #DIV/0! | BD19: ='[1]ROOT 7'!P37 -> #DIV/0! | BE19: ='[1]ROOT 7'!P36 -> #DIV/0! | BN19: 1017.6416 | BO19: 26.854087 | BP19: 27.02975 | BQ19: 35.531692 | BR19: 35.698902
B20: Tiempo de secado | C20: 2hr~3hr | M20: 19 | N20: 92.926 | O20: 92.926 | P20: 1.25 | Q20: 1.38 | R20: 1.32 | S20: 1.34 | T20: 0.98 | U20: 1.24 | V20: 1.33 | W20: 0.006 | Y20: 1.18 | Z20: 1.22 | AA20: 1.3 | AB20: 1.13 | AC20: 1.2 | AD20: 1.14 | AH20: 1.95 | AJ20: 1.45 | AP20: 19 | AQ20: 1.42 | AR20: =AR19 -> 1.4406 | AS20: =AQ20-AR20 -> -0.0206 | AV20: 38 | AZ20: ='[1]ROOT 8'!P31 -> 0 | BA20: ='[1]ROOT 8'!P32 -> 0 | BB20: ='[1]ROOT 8'!P42 -> #DIV/0! | BC20: ='[1]ROOT 8'!P41 -> #DIV/0! | BD20: ='[1]ROOT 8'!P37 -> #DIV/0! | BE20: ='[1]ROOT 8'!P36 -> #DIV/0! | BN20: 1014.8141 | BO20: 26.985391 | BP20: 27.063 | BQ20: 35.555923 | BR20: 35.672235
B21: Humedad del material | C21: <0.04% | M21: 20 | N21: 93.038 | O21: 93.038 | P21: 1.32 | Q21: 1.32 | R21: 1.3 | S21: 1.35 | T21: 0.97 | U21: 1.21 | V21: 1.36 | W21: 0.008 | Y21: 1.21 | Z21: 1.24 | AA21: 1.27 | AB21: 1.12 | AC21: 1.19 | AD21: 1.17 | AH21: 1.95 | AJ21: 1.438 | AP21: 20 | AQ21: 1.438 | AR21: =AR20 -> 1.4406 | AS21: =AQ21-AR21 -> -0.0026 | AV21: 39 | AZ21: =[1]THKC!P31 -> 1.95664 | BA21: =[1]THKC!P32 -> 0.011140163 | BB21: =[1]THKC!P42 -> 1.695 | BC21: =[1]THKC!P41 -> 2.992 | BD21: =[1]THKC!P37 -> 1.671 | BE21: =[1]THKC!P36 -> 2.951 | BN21: 1017.5043 | BO21: 26.955826 | BP21: 26.96 | BQ21: 35.589385 | BR21: 35.685961
B22: Peso con tolerancia | C22: Weight 92.8 +/-1.5 | D22: 92.8 | E22: 1.5 | F22: =E22 -> 1.5 | G22: =D22-E22 -> 91.3 | H22: =D22+F22 -> 94.3 | I22: +/- | J22: =C22 -> Weight 92.8 +/-1.5 | K22: =CONCATENATE(D22,I22,E22) -> 92.8 +/-1.5 | M22: 21 | N22: 92.944 | O22: 92.944 | P22: 1.28 | Q22: 1.4 | R22: 1.34 | S22: 1.3 | T22: 1.04 | U22: 1.2 | V22: 1.32 | W22: 0.004 | Y22: 1.2 | Z22: 1.24 | AA22: 1.27 | AB22: 1.13 | AC22: 1.21 | AD22: 1.15 | AH22: 1.96 | AJ22: 1.42 | AP22: 21 | AQ22: 1.42 | AR22: =AR21 -> 1.4406 | AS22: =AQ22-AR22 -> -0.0206 | AV22: 40 | AZ22: =[1]THKF!P31 -> 1.44364 | BA22: =[1]THKF!P32 -> 0.015593837 | BB22: =[1]THKF!P42 -> 2.002 | BC22: =[1]THKF!P41 -> 2.138 | BD22: =[1]THKF!P37 -> 1.775 | BE22: =[1]THKF!P36 -> 1.895 | BN22: 1017.6278 | BO22: 26.908 | BP22: 27.02425 | BQ22: 35.675538 | BR22: 35.680667
B23: Espesor peak 1 | C23: 1 Peak 1.29 +/-0.15 | D23: 1.29 | E23: 0.15 | F23: =E23 -> 0.15 | G23: =D23-E23 -> 1.14 | H23: =D23+F23 -> 1.44 | I23: +/- | J23: =C23 -> 1 Peak 1.29 +/-0.15 | K23: =CONCATENATE(D23,I23,E23) -> 1.29 +/-0.15 | M23: 22 | N23: 93.243 | O23: 93.243 | P23: 1.3 | Q23: 1.35 | R23: 1.3 | S23: 1.36 | T23: 0.98 | U23: 1.24 | V23: 1.39 | W23: 0.003 | Y23: 1.19 | Z23: 1.26 | AA23: 1.3 | AB23: 1.14 | AC23: 1.21 | AD23: 1.19 | AH23: 1.95 | AJ23: 1.44 | AP23: 22 | AQ23: 1.44 | AR23: =AR22 -> 1.4406 | AS23: =AQ23-AR23 -> -0.0006 | AV23: 41 | AZ23: =[1]Weight!P31 -> 93.084272 | BA23: =[1]Weight!P32 -> 0.079159432 | BB23: =[1]Weight!P42 -> 5.119 | BC23: =[1]Weight!P41 -> 6.316 | BD23: =[1]Weight!P37 -> 5.344 | BE23: =[1]Weight!P36 -> 6.594 | BN23: 1017.9435 | BO23: 26.902348 | BP23: 27.06225 | BQ23: 35.566308 | BR23: 35.672
B24: Espesor peak 2 | C24: 2 Peak 1.36 +/-0.15 | D24: 1.36 | E24: 0.15 | F24: =E24 -> 0.15 | G24: =D24-E24 -> 1.21 | H24: =D24+F24 -> 1.51 | I24: +/- | J24: =C24 -> 2 Peak 1.36 +/-0.15 | K24: =CONCATENATE(D24,I24,E24) -> 1.36 +/-0.15 | M24: 23 | N24: 93.037 | O24: 93.037 | P24: 1.23 | Q24: 1.35 | R24: 1.34 | S24: 1.32 | T24: 1.02 | U24: 1.25 | V24: 1.33 | W24: 0.007 | Y24: 1.22 | Z24: 1.21 | AA24: 1.26 | AB24: 1.17 | AC24: 1.18 | AD24: 1.13 | AH24: 1.96 | AJ24: 1.46 | AP24: 23 | AQ24: 1.46 | AR24: =AR23 -> 1.4406 | AS24: =AQ24-AR24 -> 0.0194 | AV24: 42 | BN24: 1017.3671 | BO24: 26.934087 | BP24: 27.03875 | BQ24: 35.589385 | BR24: 35.690275
B25: Espesor peak 3 | C25: 3 Peak 1.29 +/-0.15 | D25: 1.29 | E25: 0.15 | F25: =E25 -> 0.15 | G25: =D25-E25 -> 1.14 | H25: =D25+F25 -> 1.44 | I25: +/- | J25: =C25 -> 3 Peak 1.29 +/-0.15 | K25: =CONCATENATE(D25,I25,E25) -> 1.29 +/-0.15 | M25: 24 | N25: 93.16 | O25: 93.16 | P25: 1.25 | Q25: 1.36 | R25: 1.25 | S25: 1.35 | T25: 1.04 | U25: 1.18 | V25: 1.29 | W25: 0.001 | Y25: 1.16 | Z25: 1.23 | AA25: 1.28 | AB25: 1.17 | AC25: 1.23 | AD25: 1.13 | AH25: 1.94 | AJ25: 1.44 | AP25: 24 | AQ25: 1.44 | AR25: =AR24 -> 1.4406 | AS25: =AQ25-AR25 -> -0.0006 | AV25: 43 | BN25: 1016.8867 | BO25: 26.940174 | BP25: 27.065 | BQ25: 35.599385 | BR25: 35.697922
B26: Espesor peak 4 | C26: 4 Peak 1.35 +/-0.15 | D26: 1.35 | E26: 0.15 | F26: =E26 -> 0.15 | G26: =D26-E26 -> 1.2 | H26: =D26+F26 -> 1.5 | I26: +/- | J26: =C26 -> 4 Peak 1.35 +/-0.15 | K26: =CONCATENATE(D26,I26,E26) -> 1.35 +/-0.15 | M26: 25 | N26: 92.691 | O26: 93.003 | P26: 1.3 | Q26: 1.34 | R26: 1.34 | S26: 1.36 | T26: 0.96 | U26: 1.2 | V26: 1.37 | W26: 0.001 | Y26: 1.22 | Z26: 1.21 | AA26: 1.25 | AB26: 1.11 | AC26: 1.22 | AD26: 1.19 | AH26: 1.95 | AJ26: 1.44 | AP26: 25 | AQ26: 1.44 | AR26: =AR25 -> 1.4406 | AS26: =AQ26-AR26 -> -0.0006 | AV26: 44 | BN26: 1014.2102 | BO26: 26.882348 | BP26: 27.037 | BQ26: 35.565154 | BR26: 35.677137
B27: Espesor peak 5 | C27: 5 Peak 1.02 +/-0.15 | D27: 1.02 | E27: 0.15 | F27: =E27 -> 0.15 | G27: =D27-E27 -> 0.87 | H27: =D27+F27 -> 1.17 | I27: +/- | J27: =C27 -> 5 Peak 1.02 +/-0.15 | K27: =CONCATENATE(D27,I27,E27) -> 1.02 +/-0.15 | M27: 26 | N27: 93.092 | O27: 93.092 | P27: 1.25 | Q27: 1.31 | R27: 1.3 | S27: 1.3 | T27: 0.98 | U27: 1.22 | V27: 1.3 | W27: 0.002 | Y27: 1.18 | Z27: 1.23 | AA27: 1.3 | AB27: 1.15 | AC27: 1.24 | AD27: 1.18 | AH27: 1.95 | AJ27: 1.47 | AP27: 26 | AQ27: 1.47 | AR27: =AR26 -> 1.4406 | AS27: =AQ27-AR27 -> 0.0294 | AV27: 45 | BN27: 1015.9808 | BO27: 27.037565 | BP27: 27.0415 | BQ27: 35.556308 | BR27: 35.697922
B28: Espesor peak 6 | C28: 6 Peak 1.21 +/-0.15 | D28: 1.21 | E28: 0.15 | F28: =E28 -> 0.15 | G28: =D28-E28 -> 1.06 | H28: =D28+F28 -> 1.36 | I28: +/- | J28: =C28 -> 6 Peak 1.21 +/-0.15 | K28: =CONCATENATE(D28,I28,E28) -> 1.21 +/-0.15 | M28: 27 | N28: 92.915 | O28: 92.915 | P28: 1.28 | Q28: 1.36 | R28: 1.27 | S28: 1.37 | T28: 1.04 | U28: 1.18 | V28: 1.35 | W28: 0.005 | Y28: 1.22 | Z28: 1.18 | AA28: 1.27 | AB28: 1.11 | AC28: 1.23 | AD28: 1.17 | AH28: 1.98 | AJ28: 1.47 | AP28: 27 | AQ28: 1.47 | AR28: =AR27 -> 1.4406 | AS28: =AQ28-AR28 -> 0.0294 | AV28: 46 | BN28: 1018.52 | BO28: 26.949739 | BP28: 27.03275 | BQ28: 35.635538 | BR28: 35.702039
B29: Espesor peak 7 | C29: 7 Peak 1.37+/-0.20 | D29: 1.37 | E29: 0.2 | F29: =E29 -> 0.2 | G29: =D29-E29 -> 1.17 | H29: =D29+F29 -> 1.57 | I29: +/- | J29: =C29 -> 7 Peak 1.37+/-0.20 | K29: =CONCATENATE(D29,I29,E29) -> 1.37 +/-0.2 | M29: 28 | N29: 93.134 | O29: 93.134 | P29: 1.27 | Q29: 1.39 | R29: 1.3 | S29: 1.34 | T29: 0.99 | U29: 1.23 | V29: 1.31 | W29: 0.004 | Y29: 1.21 | Z29: 1.24 | AA29: 1.29 | AB29: 1.13 | AC29: 1.2 | AD29: 1.21 | AH29: 1.96 | AJ29: 1.43 | AP29: 28 | AQ29: 1.43 | AR29: =AR28 -> 1.4406 | AS29: =AQ29-AR29 -> -0.0106 | AV29: 47 | BN29: 1017.6553 | BO29: 27.063652 | BP29: 27.027 | BQ29: 35.518231 | BR29: 35.688706
B30: Espesor peak 8 | F30: =E30 -> 0 | G30: =D30-E30 -> 0 | H30: =D30+F30 -> 0 | I30: +/- | J30: =C30 -> 0 | K30: =CONCATENATE(D30,I30,E30) -> +/- | M30: 29 | N30: 92.93 | O30: 92.93 | P30: 1.32 | Q30: 1.32 | R30: 1.34 | S30: 1.31 | T30: 0.99 | U30: 1.21 | V30: 1.39 | W30: 0.001 | Y30: 1.18 | Z30: 1.22 | AA30: 1.26 | AB30: 1.17 | AC30: 1.25 | AD30: 1.16 | AH30: 1.95 | AJ30: 1.44 | AP30: 29 | AQ30: 1.44 | AR30: =AR29 -> 1.4406 | AS30: =AQ30-AR30 -> -0.0006 | AV30: 48 | BN30: 1016.4612 | BO30: 26.952348 | BP30: 27.0445 | BQ30: 35.560154 | BR30: 35.667137
B31: Espesor peak 9 | G31: =D31-E31 -> 0 | H31: =D31+F31 -> 0 | I31: +/- | J31: =C31 -> 0 | K31: =CONCATENATE(D31,I31,E31) -> +/- | M31: 30 | N31: 93.042 | O31: 93.042 | P31: 1.27 | Q31: 1.36 | R31: 1.34 | S31: 1.34 | T31: 1.04 | U31: 1.26 | V31: 1.35 | W31: 0.002 | Y31: 1.2 | Z31: 1.23 | AA31: 1.3 | AB31: 1.12 | AC31: 1.2 | AD31: 1.22 | AH31: 1.96 | AJ31: 1.44 | AP31: 30 | AQ31: 1.44 | AR31: =AR30 -> 1.4406 | AS31: =AQ31-AR31 -> -0.0006 | AV31: 49 | BN31: 1013.3867 | BO31: 26.971478 | BP31: 27.03775 | BQ31: 35.561308 | BR31: 35.664588
B32: Espesor root 1 | C32: 1 Root 1.22 +/-0.15 | D32: 1.15 | E32: 0.15 | F32: =E32 -> 0.15 | G32: =D32-E32 -> 1 | H32: =D32+F32 -> 1.3 | I32: +/- | J32: =C32 -> 1 Root 1.22 +/-0.15 | K32: =CONCATENATE(D32,I32,E32) -> 1.15 +/-0.15 | M32: 31 | O32: 93.059 | P32: 1.33 | Q32: 1.32 | R32: 1.28 | S32: 1.31 | T32: 0.96 | U32: 1.18 | V32: 1.3 | W32: 0.009 | Y32: 1.16 | Z32: 1.25 | AA32: 1.24 | AB32: 1.17 | AC32: 1.19 | AD32: 1.12 | AH32: 1.95 | AJ32: 1.45 | AP32: 31 | AQ32: 1.42 | AR32: =AR31 -> 1.4406 | AS32: =AQ32-AR32 -> -0.0206 | AV32: 50 | BN32: 1017.2847 | BO32: 26.966261 | BP32: 27.03625 | BQ32: 35.608615 | BR32: 35.678902
B33: Espesor root 2 | C33: 2 Root 1.24 +/-0.15 | D33: 1.24 | E33: 0.15 | F33: =E33 -> 0.15 | G33: =D33-E33 -> 1.09 | H33: =D33+F33 -> 1.39 | I33: +/- | J33: =C33 -> 2 Root 1.24 +/-0.15 | K33: =CONCATENATE(D33,I33,E33) -> 1.24 +/-0.15 | M33: 32 | O33: 93.031 | P33: 1.27 | Q33: 1.35 | R33: 1.32 | S33: 1.36 | T33: 0.98 | U33: 1.19 | V33: 1.28 | W33: 0.001 | Y33: 1.23 | Z33: 1.22 | AA33: 1.27 | AB33: 1.12 | AC33: 1.19 | AD33: 1.15 | AH33: 1.95 | AJ33: 1.48 | AP33: 32 | AQ33: 1.48 | AR33: =AR32 -> 1.4406 | AS33: =AQ33-AR33 -> 0.0394 | AV33: 51 | BN33: 1019.1102 | BO33: 26.919304 | BP33: 27.03675 | BQ33: 35.560923 | BR33: 35.690275
B34: Espesor root 3 | C34: 3 Root 1.3 +/-0.15 | D34: 1.3 | E34: 0.15 | F34: =E34 -> 0.15 | G34: =D34-E34 -> 1.15 | H34: =D34+F34 -> 1.45 | I34: +/- | J34: =C34 -> 3 Root 1.3 +/-0.15 | K34: =CONCATENATE(D34,I34,E34) -> 1.3 +/-0.15 | M34: 33 | O34: 93.179 | P34: 1.29 | Q34: 1.36 | R34: 1.32 | S34: 1.33 | T34: 0.99 | U34: 1.22 | V34: 1.36 | W34: 0.009 | Y34: 1.19 | Z34: 1.25 | AA34: 1.28 | AB34: 1.15 | AC34: 1.2 | AD34: 1.21 | AH34: 1.94 | AJ34: 1.43 | AP34: 33 | AQ34: 1.43 | AR34: =AR33 -> 1.4406 | AS34: =AQ34-AR34 -> -0.0106 | AV34: 52 | BN34: 1014.2102 | BO34: 26.941478 | BP34: 27.073 | BQ34: 35.569769 | BR34: 35.713804
B35: Espesor root 4 | C35: 4 Root 1.14 +/-0.15 | D35: 1.14 | E35: 0.15 | F35: =E35 -> 0.15 | G35: =D35-E35 -> 0.99 | H35: =D35+F35 -> 1.29 | I35: +/- | J35: =C35 -> 4 Root 1.14 +/-0.15 | K35: =CONCATENATE(D35,I35,E35) -> 1.14 +/-0.15 | M35: 34 | O35: 93.206 | P35: 1.3 | Q35: 1.33 | R35: 1.26 | S35: 1.34 | T35: 1 | U35: 1.18 | V35: 1.38 | W35: 0.006 | Y35: 1.17 | Z35: 1.22 | AA35: 1.27 | AB35: 1.18 | AC35: 1.19 | AD35: 1.13 | AH35: 1.98 | AJ35: 1.45 | AP35: 34 | AQ35: 1.45 | AR35: =AR34 -> 1.4406 | AS35: =AQ35-AR35 -> 0.0094 | AV35: 53 | BN35: 1016.9827 | BO35: 27.063652 | BP35: 27.064 | BQ35: 35.580154 | BR35: 35.676941
B36: Espesor root 5 | C36: 5 Root 1.19 +/-0.15 | D36: 1.19 | E36: 0.15 | F36: =E36 -> 0.15 | G36: =D36-E36 -> 1.04 | H36: =D36+F36 -> 1.34 | I36: +/- | J36: =C36 -> 5 Root 1.19 +/-0.15 | K36: =CONCATENATE(D36,I36,E36) -> 1.19 +/-0.15 | M36: 35 | O36: 93.028 | P36: 1.29 | Q36: 1.36 | R36: 1.3 | S36: 1.29 | T36: 0.99 | U36: 1.26 | V36: 1.3 | W36: 0.008 | Y36: 1.23 | Z36: 1.24 | AA36: 1.32 | AB36: 1.13 | AC36: 1.21 | AD36: 1.16 | AH36: 1.96 | AJ36: 1.44 | AP36: 35 | AQ36: 1.44 | AR36: =AR35 -> 1.4406 | AS36: =AQ36-AR36 -> -0.0006 | AV36: 54 | BN36: 1013.3867 | BO36: 26.960174 | BP36: 27.031 | BQ36: 35.537846 | BR36: 35.686549
B37: Espesor root 6 | C37: 6 Root 1.20+/-0.20 | D37: 1.2 | E37: 0.2 | F37: =E37 -> 0.2 | G37: =D37-E37 -> 1 | H37: =D37+F37 -> 1.4 | I37: +/- | J37: =C37 -> 6 Root 1.20+/-0.20 | K37: =CONCATENATE(D37,I37,E37) -> 1.2 +/-0.2 | M37: 36 | O37: 93.204 | P37: 1.31 | Q37: 1.31 | R37: 1.3 | S37: 1.34 | T37: 0.99 | U37: 1.17 | V37: 1.34 | W37: 0.004 | Y37: 1.21 | Z37: 1.22 | AA37: 1.27 | AB37: 1.17 | AC37: 1.25 | AD37: 1.19 | AH37: 1.95 | AJ37: 1.44 | AP37: 36 | AQ37: 1.44 | AR37: =AR36 -> 1.4406 | AS37: =AQ37-AR37 -> -0.0006 | AV37: 55 | BN37: 1021.622 | BO37: 26.932783 | BP37: 27.02 | BQ37: 35.532846 | BR37: 35.642824
B38: Espesor root 7 | F38: =E38 -> 0 | G38: =D38-E38 -> 0 | H38: =D38+F38 -> 0 | I38: +/- | J38: =C38 -> 0 | K38: =CONCATENATE(D38,I38,E38) -> +/- | M38: 37 | O38: 93.054 | P38: 1.31 | Q38: 1.31 | R38: 1.33 | S38: 1.37 | T38: 1.01 | U38: 1.24 | V38: 1.34 | W38: 0.004 | Y38: 1.22 | Z38: 1.24 | AA38: 1.29 | AB38: 1.13 | AC38: 1.24 | AD38: 1.22 | AH38: 1.96 | AJ38: 1.47 | AP38: 37 | AQ38: 1.47 | AR38: =AR37 -> 1.4406 | AS38: =AQ38-AR38 -> 0.0294 | AV38: 56 | BN38: 1015.871 | BO38: 26.906261 | BP38: 27.05 | BQ38: 35.560923 | BR38: 35.680471
B39: Espesor root 8 | G39: =D39-E39 -> 0 | H39: =D39+F39 -> 0 | I39: +/- | J39: =C39 -> 0 | K39: =CONCATENATE(D39,I39,E39) -> +/- | M39: 38 | O39: 93.105 | P39: 1.26 | Q39: 1.39 | R39: 1.3 | S39: 1.31 | T39: 0.96 | U39: 1.19 | V39: 1.32 | W39: 0.005 | Y39: 1.17 | Z39: 1.22 | AA39: 1.27 | AB39: 1.16 | AC39: 1.23 | AD39: 1.21 | AH39: 1.98 | AJ39: 1.43 | AP39: 38 | AQ39: 1.43 | AR39: =AR38 -> 1.4406 | AS39: =AQ39-AR39 -> -0.0106 | AV39: 57 | BN39: 1013.3867 | BO39: 26.928435 | BP39: 27.05975 | BQ39: 35.583231 | BR39: 35.687333
B40: Espesor root 9 | G40: =D40-E40 -> 0 | H40: =D40+F40 -> 0 | I40: +/- | J40: =C40 -> 0 | K40: =CONCATENATE(D40,I40,E40) -> +/- | M40: 39 | O40: 93.081 | P40: 1.32 | Q40: 1.33 | R40: 1.29 | S40: 1.31 | T40: 0.98 | U40: 1.23 | V40: 1.37 | W40: 0.001 | Y40: 1.2 | Z40: 1.23 | AA40: 1.31 | AB40: 1.15 | AC40: 1.17 | AD40: 1.15 | AH40: 1.96 | AJ40: 1.45 | AP40: 39 | AQ40: 1.42 | AR40: =AR39 -> 1.4406 | AS40: =AQ40-AR40 -> -0.0206 | AV40: 58 | BN40: 1016.6533 | BO40: 27.037565 | BP40: 27.03325 | BQ40: 35.629385 | BR40: 35.725569
...

Sheet Data
B1: 7th PEAK | C1: 6th PEAK | D1: 5th PEAK | E1: 4th PEAK | F1: 3rd PEAK | G1: 2nd PEAK | H1: 1st PEAK | I1: 6th ROOT | J1: 5th ROOT | K1: 4th ROOT | L1: 3rd ROOT | M1: 2nd ROOT | N1: 1st ROOT | O1: Chico Ø 1 (Basic 2.0) | P1: Grande Ø 1 (Basic 2.0) | Q1: PEQUEÑA "R" | T1: Grande Ø 2
A2: WEIGHT | B2: Peak 1 | C2: Peak 2 | D2: Peak 3 | E2: Peak 4 | F2: Peak 5 | G2: Peak 6 | H2: Peak 7 | I2: Root 1 | J2: Root 2 | K2: Root 3 | L2: Root 4 | M2: Root 5 | N2: Root 6 | O2: THKC | P2: THKF
A3: 93.016 | B3: 1.29 | C3: 1.34 | D3: 1.34 | E3: 1.34 | F3: 0.98 | G3: 1.19 | H3: 1.37 | I3: 1.19 | J3: 1.26 | K3: 1.27 | L3: 1.17 | M3: 1.17 | N3: 1.2 | O3: 1.94 | P3: 1.42 | Q3: 1.85 | R3: 1.95 | S3: 1.82 | T3: 2.38 | U3: 2.36 | V3: 2.36
A4: 93.206 | B4: 1.25 | C4: 1.35 | D4: 1.31 | E4: 1.32 | F4: 0.98 | G4: 1.18 | H4: 1.29 | I4: 1.2 | J4: 1.2 | K4: 1.28 | L4: 1.14 | M4: 1.2 | N4: 1.17 | O4: 1.95 | P4: 1.43 | Q4: 1.86 | R4: 1.96 | S4: 1.83 | T4: 2.38 | U4: 2.36 | V4: 2.36
A6: 93.057 | B6: 1.33 | C6: 1.32 | D6: 1.33 | E6: 1.38 | F6: 0.97 | G6: 1.21 | H6: 1.31 | I6: 1.2 | J6: 1.22 | K6: 1.24 | L6: 1.16 | M6: 1.21 | N6: 1.17 | O6: 1.95 | P6: 1.44 | Q6: 1.79 | R6: 1.79 | S6: 1.78 | T6: 2.38 | U6: 2.4 | V6: 2.36
A7: 93.003 | B7: 1.28 | C7: 1.4 | D7: 1.29 | E7: 1.34 | F7: 0.98 | G7: 1.16 | H7: 1.32 | I7: 1.19 | J7: 1.26 | K7: 1.27 | L7: 1.12 | M7: 1.2 | N7: 1.16 | O7: 1.96 | P7: 1.43 | Q7: 1.79 | R7: 1.8 | S7: 1.8 | T7: 2.36 | U7: 2.4 | V7: 2.37
A8: 93.003 | B8: 1.28 | C8: 1.4 | D8: 1.29 | E8: 1.34 | F8: 0.98 | G8: 1.16 | H8: 1.32 | I8: 1.19 | J8: 1.26 | K8: 1.27 | L8: 1.12 | M8: 1.2 | N8: 1.16 | O8: 1.96 | P8: 1.43 | Q8: 1.79 | R8: 1.8 | S8: 1.8 | T8: 2.36 | U8: 2.4 | V8: 2.37
A9: 93.192 | B9: 1.3 | C9: 1.35 | D9: 1.32 | E9: 1.37 | F9: 1 | G9: 1.22 | H9: 1.34 | I9: 1.21 | J9: 1.23 | K9: 1.25 | L9: 1.14 | M9: 1.23 | N9: 1.18 | O9: 1.95 | P9: 1.46 | Q9: 1.82 | R9: 1.91 | S9: 1.89 | T9: 2.31 | U9: 2.27 | V9: 2.3
A10: 93.055 | B10: 1.28 | C10: 1.37 | D10: 1.27 | E10: 1.31 | F10: 1.04 | G10: 1.22 | H10: 1.33 | I10: 1.22 | J10: 1.2 | K10: 1.25 | L10: 1.1 | M10: 1.19 | N10: 1.17 | O10: 1.96 | P10: 1.45 | Q10: 1.86 | R10: 1.87 | S10: 1.88 | T10: 2.4 | U10: 2.38 | V10: 2.32
A11: 93.13 | B11: 1.3 | C11: 1.34 | D11: 1.33 | E11: 1.35 | F11: 1 | G11: 1.18 | H11: 1.3 | I11: 1.19 | J11: 1.26 | K11: 1.3 | L11: 1.12 | M11: 1.23 | N11: 1.14 | O11: 1.95 | P11: 1.43 | Q11: 1.96 | R11: 1.87 | S11: 1.86 | T11: 2.4 | U11: 2.36 | V11: 2.38
A12: 93.006 | B12: 1.26 | C12: 1.37 | D12: 1.28 | E12: 1.36 | F12: 0.98 | G12: 1.21 | H12: 1.32 | I12: 1.21 | J12: 1.24 | K12: 1.29 | L12: 1.15 | M12: 1.17 | N12: 1.14 | O12: 1.95 | P12: 1.43 | Q12: 1.93 | R12: 1.89 | S12: 1.9 | T12: 2.41 | U12: 2.38 | V12: 2.36
A13: 93.154 | B13: 1.25 | C13: 1.37 | D13: 1.32 | E13: 1.32 | F13: 1.02 | G13: 1.18 | H13: 1.36 | I13: 1.2 | J13: 1.23 | K13: 1.27 | L13: 1.11 | M13: 1.18 | N13: 1.17 | O13: 1.97 | P13: 1.45 | Q13: 1.83 | R13: 1.8 | S13: 1.92 | T13: 2.32 | U13: 2.33 | V13: 2.3
A14: 92.905 | B14: 1.33 | C14: 1.35 | D14: 1.29 | E14: 1.33 | F14: 1.01 | G14: 1.22 | H14: 1.3 | I14: 1.17 | J14: 1.22 | K14: 1.3 | L14: 1.13 | M14: 1.25 | N14: 1.14 | O14: 1.95 | P14: 1.45 | Q14: 1.83 | R14: 1.8 | S14: 1.92 | T14: 2.32 | U14: 2.33 | V14: 2.3
A15: 92.94 | B15: 1.31 | C15: 1.38 | D15: 1.31 | E15: 1.38 | F15: 0.97 | G15: 1.17 | H15: 1.3 | I15: 1.2 | J15: 1.25 | K15: 1.26 | L15: 1.13 | M15: 1.19 | N15: 1.17 | O15: 1.96 | P15: 1.48 | Q15: 1.84 | R15: 1.81 | S15: 1.93 | T15: 2.33 | U15: 2.32 | V15: 2.31
... A132: 93.006 | B132: 1.29 | C132: 1.31 | D132: 1.29 | E132: 1.31 | F132: 1.03 | G132: 1.19 | H132: 1.37 | I132: 1.17 | J132: 1.22 | K132: 1.25 | L132: 1.12 | M132: 1.23 | N132: 1.13 | O132: 1.95 | P132: 1.43 | Q132: 1.84 | R132: 1.86 | S132: 1.9 | T132: 2.38 | U132: 2.39 | V132: 2.35

Sheet 14DAJ9
A1: KUNHWA MEXICO | F1: SPC
B2: KUNHWA # : | C2: 14DAJ9000 (10433939) | H2: DATE & TIME : | N2: PART WIEGHT : | O2: 92.8 ± 1.5g
B3: REVISION : | C3: ´01 | F3: LOTE: | H3: OPERATOR NAME :
B4: MACHINE N° : | C4: TPE10 | H4: MATERIAL : | I4: PB420 | K4: Approval by Ope: | M4: Approval by Pro:
B5: STANDARD CYCLE TIME : | F5: E-TIME: | H5: Custom & Model : | I5: GM T1XX | K5: Sign | M5: Sign
B6: Cliente: GKN | F6: D-TIME: | G6: PART #1 | I6: =Data!A3 -> 93.016 | L6: PART #2 | N6: =Data!A4 -> 93.206
A7: obtener la aprobación de la calidad después de la configuración !! | G7: SECTOR | J7: R | K7: FlowLine | L7: SECTOR | O7: R | P7: FlowLine
A8: Inspection No. | B8: Inspection region | C8: Spec | F8: Device | G8: A | H8: B | I8: C | J8: <0.15 | K8: <-10% | L8: A | M8: B | N8: C | O8: <0.15 | P8: <-10%
A9: ** | B9: PEQUEÑA "R" | C9: MIN 1.8 | F9: Caliper | G9: =Data!Q3 -> 1.85 | H9: =Data!R3 -> 1.95 | I9: =Data!S3 -> 1.82 | J9: =(MAX(G9:I9)-MIN(G9:I9)) -> 0.13 | K9: * | L9: =Data!Q4 -> 1.86 | M9: =Data!R4 -> 1.96 | N9: =Data!S4 -> 1.83 | O9: =(MAX(L9:N9)-MIN(L9:N9)) -> 0.13 | P9: *
A10: KHB 20 | B10: Chico Ø 1 (Basic 2.0) | C10: 1.8715 | D10: 2 | E10: 2.1285 | F10: Digital Ind+Fix S077 | G10: =Data!O3 -> 1.94 | H10: =G10+S10 -> 1.97 | I10: =G10-S10 -> 1.91 | J10: =(MAX(G10:I10)-MIN(G10:I10)) -> 0.06 | L10: =Data!O4 -> 1.95 | M10: =L10+X10 -> 1.97 | N10: =L10-X10 -> 1.93 | O10: =(MAX(L10:N10)-MIN(L10:N10)) -> 0.04 | P10: * | S10: 0.03 | X10: 0.02
A11: KHB 01 | B11: 1st PEAK | C11: 1.2014 | D11: 1.37 | E11: 1.5386 | F11: Digital Ind | G11: =Data!H3 -> 1.37 | H11: =G11+S11 -> 1.42 | I11: =G11-S11 -> 1.32 | J11: =(MAX(G11:I11)-MIN(G11:I11)) -> 0.1 | L11: =Data!H4 -> 1.29 | M11: =L11+X11 -> 1.3 | N11: =L11-X11 -> 1.28 | O11: =(MAX(L11:N11)-MIN(L11:N11)) -> 0.02 | S11: 0.05 | T11: 0.1 | X11: 0.01
A12: KHB 02 | B12: 1st ROOT | C12: 1.028 | D12: 1.2 | E12: 1.372 | F12: Digital Ind+Fix K | G12: =Data!N3 -> 1.2 | H12: =G12+S12 -> 1.26 | I12: =G12-S12 -> 1.14 | J12: =(MAX(G12:I12)-MIN(G12:I12)) -> 0.12 | L12: =Data!N4 -> 1.17 | M12: =L12+X12 -> 1.2 | N12: =L12-X12 -> 1.14 | O12: =(MAX(L12:N12)-MIN(L12:N12)) -> 0.06 | S12: 0.06 | X12: 0.03
A13: KHB 03 | B13: 2nd PEAK | C13: 1.0872 | D13: 1.21 | E13: 1.3328 | F13: Digital Ind | G13: =Data!G3 -> 1.19 | H13: =G13+S13 -> 1.23 | I13: =G13-S13 -> 1.15 | J13: =(MAX(G13:I13)-MIN(G13:I13)) -> 0.08 | L13: =Data!G4 -> 1.18 | M13: =L13+X13 -> 1.22 | N13: =L13-X13 -> 1.14 | O13: =(MAX(L13:N13)-MIN(L13:N13)) -> 0.08 | S13: 0.04 | X13: 0.04
A14: KHB 04 | B14: 2nd ROOT | C14: 1.0668 | D14: 1.19 | E14: 1.3132 | F14: Digital Ind+Fix K | G14: =Data!M3 -> 1.17 | H14: =G14+S14 -> 1.23 | I14: =G14-S14 -> 1.11 | J14: =(MAX(G14:I14)-MIN(G14:I14)) -> 0.12 | L14: =Data!M4 -> 1.2 | M14: =L14+X14 -> 1.22 | N14: =L14-X14 -> 1.18 | O14: =(MAX(L14:N14)-MIN(L14:N14)) -> 0.04 | S14: 0.06 | X14: 0.02
A15: KHB 05 | B15: 3rd PEAK | C15: 0.8934 | D15: 1.02 | E15: 1.1466 | F15: Digital Ind | G15: =Data!F3 -> 0.98 | H15: =G15+S15 -> 1 | I15: =G15-S15 -> 0.96 | J15: =(MAX(G15:I15)-MIN(G15:I15)) -> 0.04 | L15: =Data!F4 -> 0.98 | M15: =L15+X15 -> 1.04 | N15: =L15-X15 -> 0.92 | O15: =(MAX(L15:N15)-MIN(L15:N15)) -> 0.12 | S15: 0.02 | X15: 0.06
A16: KHB 06 | B16: 3rd ROOT | C16: 1.0158 | D16: 1.14 | E16: 1.2642 | F16: Digital Ind+Fix K | G16: =Data!L3 -> 1.17 | H16: =G16+S16 -> 1.18 | I16: =G16-S16 -> 1.16 | J16: =(MAX(G16:I16)-MIN(G16:I16)) -> 0.02 | L16: =Data!L4 -> 1.14 | M16: =L16+X16 -> 1.16 | N16: =L16-X16 -> 1.12 | O16: =(MAX(L16:N16)-MIN(L16:N16)) -> 0.04 | S16: 0.01 | X16: 0.02
A17: KHB 07 | B17: 4th PEAK | C17: 1.23 | D17: 1.35 | E17: 1.47 | F17: Digital Ind | G17: =Data!E3 -> 1.34 | H17: =G17+S17 -> 1.37 | I17: =G17-S17 -> 1.31 | J17: =(MAX(G17:I17)-MIN(G17:I17)) -> 0.06 | L17: =Data!E4 -> 1.32 | M17: =L17+X17 -> 1.33 | N17: =L17-X17 -> 1.31 | O17: =(MAX(L17:N17)-MIN(L17:N17)) -> 0.02 | S17: 0.03 | X17: 0.01
A18: KHB 08 | B18: 4th ROOT | C18: 1.179 | D18: 1.3 | E18: 1.421 | F18: Digital Ind+Fix K | G18: =Data!K3 -> 1.27 | H18: =G18+S18 -> 1.31 | I18: =G18-S18 -> 1.23 | J18: =(MAX(G18:I18)-MIN(G18:I18)) -> 0.08 | L18: =Data!K4 -> 1.28 | M18: =L18+X18 -> 1.31 | N18: =L18-X18 -> 1.25 | O18: =(MAX(L18:N18)-MIN(L18:N18)) -> 0.06 | S18: 0.04 | X18: 0.03
A19: KHB 09 | B19: 5th PEAK | C19: 1.1688 | D19: 1.29 | E19: 1.4112 | F19: Digital Ind | G19: =Data!D3 -> 1.34 | H19: =G19+S19 -> 1.36 | I19: =G19-S19 -> 1.32 | J19: =(MAX(G19:I19)-MIN(G19:I19)) -> 0.04 | L19: =Data!D4 -> 1.31 | M19: =L19+X19 -> 1.35 | N19: =L19-X19 -> 1.27 | O19: =(MAX(L19:N19)-MIN(L19:N19)) -> 0.08 | S19: 0.02 | X19: 0.04
A20: KHB 10 | B20: 5th ROOT | C20: 1.1178 | D20: 1.24 | E20: 1.3622 | F20: Digital Ind+Fix K | G20: =Data!J3 -> 1.26 | H20: =G20+S20 -> 1.32 | I20: =G20-S20 -> 1.2 | J20: =(MAX(G20:I20)-MIN(G20:I20)) -> 0.12 | L20: =Data!J4 -> 1.2 | M20: =L20+X20 -> 1.23 | N20: =L20-X20 -> 1.17 | O20: =(MAX(L20:N20)-MIN(L20:N20)) -> 0.06 | S20: 0.06 | X20: 0.03
A21: KHB 11 | B21: 6th PEAK | C21: 1.2402 | D21: 1.36 | E21: 1.4798 | F21: Digital Ind | G21: =Data!C3 -> 1.34 | H21: =G21+S21 -> 1.39 | I21: =G21-S21 -> 1.29 | J21: =(MAX(G21:I21)-MIN(G21:I21)) -> 0.1 | L21: =Data!C4 -> 1.35 | M21: =L21+X21 -> 1.4 | N21: =L21-X21 -> 1.3 | O21: =(MAX(L21:N21)-MIN(L21:N21)) -> 0.1 | S21: 0.05 | X21: 0.05
A22: KHB 12 | B22: 6th ROOT | C22: 1.0974 | D22: 1.22 | E22: 1.3426 | F22: Digital Ind+Fix K | G22: =Data!I3 -> 1.19 | H22: =G22+S22 -> 1.22 | I22: =G22-S22 -> 1.16 | J22: =(MAX(G22:I22)-MIN(G22:I22)) -> 0.06 | L22: =Data!I4 -> 1.2 | M22: =L22+X22 -> 1.26 | N22: =L22-X22 -> 1.14 | O22: =(MAX(L22:N22)-MIN(L22:N22)) -> 0.12 | S22: 0.03 | X22: 0.06
A23: KHB 13 | B23: 7th PEAK | C23: 1.1688 | D23: 1.29 | E23: 1.4112 | F23: Digital Ind | G23: =Data!B3 -> 1.29 | H23: =G23+S23 -> 1.33 | I23: =G23-S23 -> 1.25 | J23: =(MAX(G23:I23)-MIN(G23:I23)) -> 0.08 | L23: =Data!B4 -> 1.25 | M23: =L23+X23 -> 1.29 | N23: =L23-X23 -> 1.21 | O23: =(MAX(L23:N23)-MIN(L23:N23)) -> 0.08 | S23: 0.04 | X23: 0.04
A24: KHB 14 | B24: Grande Ø 1 (Basic 2.0) | C24: 1.332 | D24: 1.45 | E24: 1.568 | F24: Digital Ind+Fix L078 | G24: =Data!P3 -> 1.42 | H24: =G24+S24 -> 1.45 | I24: =G24-S24 -> 1.39 | J24: =(MAX(G24:I24)-MIN(G24:I24)) -> 0.06 | L24: =Data!P4 -> 1.43 | M24: =L24+X24 -> 1.49 | N24: =L24-X24 -> 1.37 | O24: =(MAX(L24:N24)-MIN(L24:N24)) -> 0.12 | S24: 0.03 | X24: 0.06
A25: KHB 15 | B25: Grande Ø 2 | C25: 2.45 MAX | F25: Digital Ind+Fix K | G25: =Data!T3 -> 2.38 | H25: =Data!U3 -> 2.36 | I25: =Data!V3 -> 2.36 | J25: =(MAX(G25:I25)-MIN(G25:I25)) -> 0.02 | L25: =Data!T4 -> 2.38 | M25: =Data!U4 -> 2.36 | N25: =Data!V4 -> 2.36 | O25: =(MAX(L25:N25)-MIN(L25:N25)) -> 0.02

Sheet Hoja4
A1: NP | B1: Fecha | C1: Hora | D1: Peso | E1: CalA | F1: CalB | G1: CalC | H1: RA | I1: RB | J1: RC | K1: P1A | L1: P1B | M1: P1C | N1: P1rA | O1: P1rB | P1: P1rC | Q1: P2A | R1: P2B | S1: P2C | T1: P2rA | U1: P2rB | V1: P2rC | W1: P3A | X1: P3B | Y1: P3C | Z1: P3rA | AA1: P3rB | AB1: P3rC | AC1: P4A | AD1: P4B | AE1: P4C | AF1: P4rA | AG1: P4rB | AH1: P4rC | AI1: P5A | AJ1: P5B | AK1: P5C | AL1: P5rA | AM1: P5rB | AN1: P5rC | AO1: P6A | AP1: P6B | AQ1: P6C | AR1: P6rA | AS1: P6rB | AT1: P6rC | AU1: P7A | AV1: P7B | AW1: P7C | AX1: P7rA | AY1: P7rB | AZ1: P7rC | BA1: P8A | BB1: P8B | BC1: P8C | BD1: P8rA | BE1: P8rB | BF1: P8rC | BG1: P9A | BH1: P9B | BI1: P9C | BJ1: P9rA | BK1: P9rB | BL1: P9rC | BM1: P10A | BN1: P10B | BO1: P10C | BP1: P10rA | BQ1: P10rB | BR1: P10rC | BS1: P42A | BT1: P42B | BU1: P42C | BV1: P42rA | BW1: P42rB | BX1: P42rC | BY1: D1A | BZ1: D1B | CA1: D1C | CB1: D2A | CC1: D2B | CD1: D2C
A2: 10433939 | B2: 46169 | C2: 0.84261574 | D2: 93.352 | E2: 1.79 | F2: 1.79 | G2: 1.78 | H2: 1.93 | I2: 1.9 | J2: 1.97 | K2: 1.21 | L2: 1.15 | M2: 1.2 | N2: 1.16 | O2: 1.13 | P2: 1.15 | Q2: 1.14 | R2: 1.11 | S2: 1.13 | T2: 1.23 | U2: 1.2 | V2: 1.23 | W2: 1.01 | X2: 0.96 | Y2: 0.95 | Z2: 1.13 | AA2: 1.12 | AB2: 1.13 | AC2: 1.26 | AD2: 1.26 | AE2: 1.2 | AF2: 1.32 | AG2: 1.3 | AH2: 1.35 | AI2: 1.3 | AJ2: 1.27 | AK2: 1.1 | AL2: 1.25 | AM2: 1.26 | AN2: 1.29 | AO2: 1.36 | AP2: 1.21 | AQ2: 1.2 | AR2: 1.26 | AS2: 1.29 | AT2: 1.3 | AU2: 1.36 | AV2: 1.33 | AW2: 1.26 | BY2: 1.52 | BZ2: 1.46 | CA2: 1.5 | CB2: 2.38 | CC2: 2.4 | CD2: 2.36
A3: 10433939 | B3: 46169 | C3: 0.84394676 | D3: 93.35 | E3: 1.79 | F3: 1.8 | G3: 1.8 | H3: 1.94 | I3: 1.92 | J3: 1.96 | K3: 1.26 | L3: 1.3 | M3: 1.29 | N3: 1.16 | O3: 1.13 | P3: 1.15 | Q3: 1.14 | R3: 1.12 | S3: 1.13 | T3: 1.23 | U3: 1.2 | V3: 1.23 | W3: 1 | X3: 0.97 | Y3: 1 | Z3: 1.13 | AA3: 1.12 | AB3: 1.14 | AC3: 1.28 | AD3: 1.29 | AE3: 1.3 | AF3: 1.32 | AG3: 1.3 | AH3: 1.35 | AI3: 1.36 | AJ3: 1.3 | AK3: 1.32 | AL3: 1.26 | AM3: 1.25 | AN3: 1.29 | AO3: 1.4 | AP3: 1.38 | AQ3: 1.39 | AR3: 1.26 | AS3: 1.29 | AT3: 1.3 | AU3: 1.34 | AV3: 1.32 | AW3: 1.27 | BY3: 1.52 | BZ3: 1.46 | CA3: 1.5 | CB3: 2.36 | CC3: 2.4 | CD3: 2.37
A4: 10433939 | B4: 46169 | C4: 0.85715278 | D4: 92.697 | E4: 1.82 | F4: 1.91 | G4: 1.89 | H4: 1.92 | I4: 1.89 | J4: 1.91 | K4: 1.33 | L4: 1.25 | M4: 1.33 | N4: 1.16 | O4: 1.14 | P4: 1.16 | Q4: 1.15 | R4: 1.08 | S4: 1.16 | T4: 1.2 | U4: 1.19 | V4: 1.22 | W4: 1.06 | X4: 0.96 | Y4: 0.99 | Z4: 1.13 | AA4: 1.12 | AB4: 1.14 | AC4: 1.32 | AD4: 1.29 | AE4: 1.26 | AF4: 1.29 | AG4: 1.3 | AH4: 1.31 | AI4: 1.36 | AJ4: 1.24 | AK4: 1.2 | AL4: 1.22 | AM4: 1.22 | AN4: 1.26 | AO4: 1.33 | AP4: 1.16 | AQ4: 1.19 | AR4: 1.19 | AS4: 1.2 | AT4: 1.24 | AU4: 1.17 | AV4: 1.13 | AW4: 1.15 | BY4: 1.44 | BZ4: 1.31 | CA4: 1.45 | CB4: 2.31 | CC4: 2.27 | CD4: 2.3
A5: 10433939 | B5: 46169 | C5: 0.85915509 | D5: 92.815 | E5: 1.86 | F5: 1.87 | G5: 1.88 | H5: 1.9 | I5: 1.89 | J5: 1.9 | K5: 1.29 | L5: 1.31 | M5: 1.29 | N5: 1.18 | O5: 1.16 | P5: 1.17 | Q5: 1.17 | R5: 1.14 | S5: 1.19 | T5: 1.16 | U5: 1.2 | V5: 1.21 | W5: 1.05 | X5: 1 | Y5: 0.98 | Z5: 1.16 | AA5: 1.11 | AB5: 1.1 | AC5: 1.29 | AD5: 1.26 | AE5: 1.25 | AF5: 1.31 | AG5: 1.29 | AH5: 1.28 | AI5: 1.32 | AJ5: 1.26 | AK5: 1.24 | AL5: 1.26 | AM5: 1.25 | AN5: 1.28 | AO5: 1.36 | AP5: 1.34 | AQ5: 1.3 | AR5: 1.26 | AS5: 1.27 | AT5: 1.29 | AU5: 1.35 | AV5: 1.32 | AW5: 1.31 | BY5: 1.5 | BZ5: 1.46 | CA5: 1.43 | CB5: 2.4 | CC5: 2.38 | CD5: 2.32
A6: 10433939 | B6: 46169 | C6: 0.86054398 | D6: 93.447 | E6: 1.96 | F6: 1.87 | G6: 1.86 | H6: 1.95 | I6: 1.9 | J6: 1.89 | K6: 1.28 | L6: 1.26 | M6: 1.25 | N6: 1.14 | O6: 1.12 | P6: 1.14 | Q6: 1.16 | R6: 1.16 | S6: 1.18 | T6: 1.22 | U6: 1.19 | V6: 1.22 | W6: 1.02 | X6: 0.95 | Y6: 0.99 | Z6: 1.12 | AA6: 1.1 | AB6: 1.13 | AC6: 1.32 | AD6: 1.26 | AE6: 1.28 | AF6: 1.3 | AG6: 1.32 | AH6: 1.29 | AI6: 1.2 | AJ6: 1.26 | AK6: 1.27 | AL6: 1.25 | AM6: 1.33 | AN6: 1.3 | AO6: 1.36 | AP6: 1.35 | AQ6: 1.31 | AR6: 1.3 | AS6: 1.31 | AT6: 1.31 | AU6: 1.35 | AV6: 1.3 | AW6: 1.36 | BY6: 1.51 | BZ6: 1.49 | CA6: 1.42 | CB6: 2.4 | CC6: 2.36 | CD6: 2.38
A7: 10433939 | B7: 46169 | C7: 0.86164352 | D7: 93.45 | E7: 1.93 | F7: 1.89 | G7: 1.9 | H7: 1.96 | I7: 1.92 | J7: 1.9 | K7: 1.3 | L7: 1.29 | M7: 1.21 | N7: 1.16 | O7: 1.1 | P7: 1.13 | Q7: 1.17 | R7: 1.19 | S7: 1.2 | T7: 1.16 | U7: 1.18 | V7: 1.19 | W7: 1.06 | X7: 0.97 | Y7: 1 | Z7: 1.16 | AA7: 1.15 | AB7: 1.16 | AC7: 1.31 | AD7: 1.29 | AE7: 1.39 | AF7: 1.29 | AG7: 1.3 | AH7: 1.29 | AI7: 1.26 | AJ7: 1.28 | AK7: 1.29 | AL7: 1.27 | AM7: 1.3 | AN7: 1.29 | AO7: 1.34 | AP7: 1.37 | AQ7: 1.35 | AR7: 1.29 | AS7: 1.28 | AT7: 1.29 | AU7: 1.32 | AV7: 1.32 | AW7: 1.34 | BY7: 1.5 | BZ7: 1.46 | CA7: 1.44 | CB7: 2.41 | CC7: 2.38 | CD7: 2.36
A8: 10433939 | B8: 46171 | C8: 0.70935185 | D8: 94.06 | E8: 1.83 | F8: 1.8 | G8: 1.92 | H8: 1.94 | I8: 1.9 | J8: 1.93 | K8: 1.38 | L8: 1.34 | M8: 1.35 | N8: 1.17 | O8: 1.17 | P8: 1.15 | Q8: 1.29 | R8: 1.21 | S8: 1.22 | T8: 1.18 | U8: 1.17 | V8: 1.16 | W8: 1 | X8: 0.97 | Y8: 0.96 | Z8: 1.15 | AA8: 1.11 | AB8: 1.09 | AC8: 1.35 | AD8: 1.33 | AE8: 1.32 | AF8: 1.24 | AG8: 1.23 | AH8: 1.24 | AI8: 1.34 | AJ8: 1.29 | AK8: 1.2 | AL8: 1.21 | AM8: 1.2 | AN8: 1.18 | AO8: 1.38 | AP8: 1.37 | AQ8: 1.29 | AR8: 1.18 | AS8: 1.19 | AT8: 1.2 | AU8: 1.35 | AV8: 1.33 | AW8: 1.28 | BY8: 1.49 | BZ8: 1.48 | CA8: 1.43 | CB8: 2.32 | CC8: 2.33 | CD8: 2.3
A9: 10433939 | B9: 46171 | C9: 0.71059028 | D9: 94.06 | E9: 1.83 | F9: 1.8 | G9: 1.92 | H9: 1.94 | I9: 1.9 | J9: 1.93 | K9: 1.38 | L9: 1.34 | M9: 1.35 | N9: 1.17 | O9: 1.19 | P9: 1.15 | Q9: 1.29 | R9: 1.21 | S9: 1.22 | T9: 1.18 | U9: 1.17 | V9: 1.16 | W9: 1 | X9: 0.97 | Y9: 0.96 | Z9: 1.15 | AA9: 1.11 | AB9: 1.09 | AC9: 1.35 | AD9: 1.33 | AE9: 1.32 | AF9: 1.24 | AG9: 1.23 | AH9: 1.24 | AI9: 1.34 | AJ9: 1.29 | AK9: 1.2 | AL9: 1.21 | AM9: 1.2 | AN9: 1.18 | AO9: 1.38 | AP9: 1.37 | AQ9: 1.29 | AR9: 1.18 | AS9: 1.19 | AT9: 1.2 | AU9: 1.35 | AV9: 1.33 | AW9: 1.28 | BY9: 1.49 | BZ9: 1.48 | CA9: 1.43 | CB9: 2.32 | CC9: 2.33 | CD9: 2.3
A10: 10433939 | B10: 46171 | C10: 0.71184028 | D10: 94.299 | E10: 1.84 | F10: 1.81 | G10: 1.93 | H10: 1.95 | I10: 1.92 | J10: 1.93 | K10: 1.39 | L10: 1.36 | M10: 1.35 | N10: 1.19 | O10: 1.2 | P10: 1.17 | Q10: 1.28 | R10: 1.23 | S10: 1.21 | T10: 1.19 | U10: 1.18 | V10: 1.19 | W10: 1.02 | X10: 0.99 | Y10: 0.98 | Z10: 1.17 | AA10: 1.12 | AB10: 1.1 | AC10: 1.37 | AD10: 1.34 | AE10: 1.33 | AF10: 1.26 | AG10: 1.25 | AH10: 1.26 | AI10: 1.35 | AJ10: 1.29 | AK10: 1.21 | AL10: 1.23 | AM10: 1.22 | AN10: 1.19 | AO10: 1.38 | AP10: 1.36 | AQ10: 1.3 | AR10: 1.2 | AS10: 1.22 | AT10: 1.21 | AU10: 1.35 | AV10: 1.33 | AW10: 1.29 | BY10: 1.48 | BZ10: 1.49 | CA10: 1.45 | CB10: 2.33 | CC10: 2.32 | CD10: 2.31
A11: 10433939 | B11: 46171 | C11: 0.81918981 | D11: 93.979 | E11: 1.82 | F11: 1.84 | G11: 1.86 | H11: 1.91 | I11: 1.93 | J11: 1.92 | K11: 1.34 | L11: 1.34 | M11: 1.38 | N11: 1.17 | O11: 1.16 | P11: 1.16 | Q11: 1.26 | R11: 1.21 | S11: 1.26 | T11: 1.18 | U11: 1.16 | V11: 1.18 | W11: 1 | X11: 0.97 | Y11: 0.98 | Z11: 1.1 | AA11: 1.11 | AB11: 1.1 | AC11: 1.36 | AD11: 1.3 | AE11: 1.36 | AF11: 1.25 | AG11: 1.25 | AH11: 1.24 | AI11: 1.36 | AJ11: 1.38 | AK11: 1.28 | AL11: 1.21 | AM11: 1.19 | AN11: 1.19 | AO11: 1.31 | AP11: 1.29 | AQ11: 1.28 | AR11: 1.17 | AS11: 1.19 | AT11: 1.2 | AU11: 1.39 | AV11: 1.32 | AW11: 1.29 | BY11: 1.52 | BZ11: 1.52 | CA11: 1.4 | CB11: 2.35 | CC11: 2.38 | CD11: 2.34
A12: 10433939 | B12: 46171 | C12: 0.82027778 | D12: 94.013 | E12: 1.81 | F12: 1.86 | G12: 1.84 | H12: 1.9 | I12: 1.91 | J12: 1.92 | K12: 1.36 | L12: 1.32 | M12: 1.36 | N12: 1.19 | O12: 1.17 | P12: 1.15 | Q12: 1.25 | R12: 1.2 | S12: 1.24 | T12: 1.18 | U12: 1.17 | V12: 1.16 | W12: 1.01 | X12: 0.99 | Y12: 1.03 | Z12: 1.09 | AA12: 1.1 | AB12: 1.09 | AC12: 1.39 | AD12: 1.32 | AE12: 1.34 | AF12: 1.28 | AG12: 1.27 | AH12: 1.26 | AI12: 1.34 | AJ12: 1.36 | AK12: 1.3 | AL12: 1.26 | AM12: 1.22 | AN12: 1.21 | AO12: 1.34 | AP12: 1.32 | AQ12: 1.3 | AR12: 1.19 | AS12: 1.21 | AT12: 1.19 | AU12: 1.36 | AV12: 1.3 | AW12: 1.31 | BY12: 1.5 | BZ12: 1.49 | CA12: 1.46 | CB12: 2.38 | CC12: 2.4 | CD12: 2.36
A13: 10433939 | B13: 46171 | C13: 0.82157407 | D13: 93.973 | E13: 1.86 | F13: 1.87 | G13: 1.82 | H13: 1.92 | I13: 1.91 | J13: 1.91 | K13: 1.39 | L13: 1.36 | M13: 1.37 | N13: 1.17 | O13: 1.16 | P13: 1.16 | Q13: 1.22 | R13: 1.23 | S13: 1.25 | T13: 1.16 | U13: 1.15 | V13: 1.16 | W13: 0.98 | X13: 0.96 | Y13: 0.99 | Z13: 1.1 | AA13: 1.09 | AB13: 1.09 | AC13: 1.36 | AD13: 1.31 | AE13: 1.37 | AF13: 1.23 | AG13: 1.26 | AH13: 1.25 | AI13: 1.23 | AJ13: 1.19 | AK13: 1.26 | AL13: 1.22 | AM13: 1.24 | AN13: 1.22 | AO13: 1.29 | AP13: 1.28 | AQ13: 1.3 | AR13: 1.19 | AS13: 1.22 | AT13: 1.21 | AU13: 1.38 | AV13: 1.34 | AW13: 1.29 | BY13: 1.46 | BZ13: 1.45 | CA13: 1.37 | CB13: 2.34 | CC13: 2.36 | CD13: 2.31
... A16: 10433939 | B16: 46171 | C16: 0.82532407 | D16: 93.836 | E16: 1.93 | F16: 1.86 | G16: 1.85 | H16: 1.94 | I16: 1.92 | J16: 1.93 | K16: 1.32 | L16: 1.32 | M16: 1.3 | N16: 1.16 | O16: 1.16 | P16: 1.15 | Q16: 1.2 | R16: 1.22 | S16: 1.2 | T16: 1.17 | U16: 1.18 | V16: 1.16 | W16: 1.01 | X16: 1.01 | Y16: 1 | Z16: 1.1 | AA16: 1.09 | AB16: 1.1 | AC16: 1.33 | AD16: 1.34 | AE16: 1.29 | AF16: 1.26 | AG16: 1.23 | AH16: 1.22 | AI16: 1.37 | AJ16: 1.27 | AK16: 1.27 | AL16: 1.21 | AM16: 1.22 | AN16: 1.18 | AO16: 1.33 | AP16: 1.3 | AQ16: 1.39 | AR16: 1.16 | AS16: 1.17 | AT16: 1.19 | AU16: 1.35 | AV16: 1.33 | AW16: 1.32 | BY16: 1.46 | BZ16: 1.47 | CA16: 1.48 | CB16: 2.37 | CC16: 2.38 | CD16: 2.39
A17: 10433939 | B17: 46174 | C17: 0.67606481 | D17: 93.945 | E17: 1.91 | F17: 1.81 | G17: 1.8 | H17: 1.93 | I17: 1.93 | J17: 1.91 | K17: 1.38 | L17: 1.35 | M17: 1.37 | N17: 1.19 | O17: 1.2 | P17: 1.18 | Q17: 1.26 | R17: 1.21 | S17: 1.22 | T17: 1.18 | U17: 1.19 | V17: 1.17 | X17: 0.99 | Y17: 0.95 | Z17: 1.15 | AA17: 1.13 | AB17: 1.12 | AC17: 1.37 | AD17: 1.33 | AE17: 1.3 | AF17: 1.25 | AG17: 1.24 | AH17: 1.25 | AI17: 1.36 | AJ17: 1.26 | AK17: 1.25 | AL17: 1.22 | AM17: 1.2 | AN17: 1.19 | AO17: 1.37 | AP17: 1.32 | AQ17: 1.33 | AR17: 1.17 | AS17: 1.19 | AT17: 1.2 | AU17: 1.37 | AV17: 1.33 | AW17: 1.34 | BY17: 1.48 | BZ17: 1.45 | CA17: 1.43 | CB17: 2.33 | CC17: 2.38 | CD17: 2.34
A18: 10433939 | B18: 46174 | C18: 0.67771991 | D18: 94.217 | E18: 1.92 | F18: 1.83 | G18: 1.81 | H18: 1.95 | I18: 1.94 | J18: 1.91 | K18: 1.39 | L18: 1.35 | M18: 1.38 | N18: 1.18 | O18: 1.2 | P18: 1.19 | Q18: 1.25 | R18: 1.23 | S18: 1.21 | T18: 1.19 | U18: 1.2 | V18: 1.18 | W18: 1.04 | X18: 1.01 | Y18: 0.98 | Z18: 1.17 | AA18: 1.15 | AB18: 1.11 | AC18: 1.35 | AD18: 1.36 | AE18: 1.32 | AF18: 1.27 | AG18: 1.28 | AH18: 1.27 | AI18: 1.37 | AJ18: 1.27 | AK18: 1.26 | AL18: 1.24 | AM18: 1.22 | AN18: 1.2 | AO18: 1.36 | AP18: 1.33 | AQ18: 1.35 | AR18: 1.19 | AS18: 1.21 | AT18: 1.22 | AU18: 1.38 | AV18: 1.34 | AW18: 1.35 | BY18: 1.49 | BZ18: 1.46 | CA18: 1.45 | CB18: 2.33 | CC18: 2.37 | CD18: 2.34
A19: 10433939 | B19: 46174 | C19: 0.67914352 | D19: 94.201 | E19: 1.85 | F19: 1.88 | G19: 1.99 | H19: 1.94 | I19: 1.94 | J19: 1.92 | K19: 1.38 | L19: 1.35 | M19: 1.37 | N19: 1.2 | O19: 1.21 | P19: 1.19 | Q19: 1.25 | R19: 1.2 | S19: 1.21 | T19: 1.19 | U19: 1.18 | V19: 1.17 | W19: 1.01 | X19: 1 | Y19: 0.99 | Z19: 1.15 | AA19: 1.13 | AB19: 1.14 | AC19: 1.36 | AD19: 1.33 | AE19: 1.31 | AF19: 1.26 | AG19: 1.24 | AH19: 1.26 | AI19: 1.36 | AJ19: 1.26 | AK19: 1.35 | AL19: 1.22 | AM19: 1.2 | AN19: 1.23 | AO19: 1.35 | AP19: 1.33 | AQ19: 1.36 | AR19: 1.18 | AS19: 1.2 | AT19: 1.19 | AU19: 1.36 | AV19: 1.34 | AW19: 1.35 | BY19: 1.48 | BZ19: 1.45 | CA19: 1.43 | CB19: 2.33 | CC19: 2.37 | CD19: 2.33
A20: 10433939 | B20: 46174 | C20: 0.68047454 | D20: 94.206 | E20: 1.86 | F20: 1.87 | G20: 1.97 | H20: 1.93 | I20: 1.94 | J20: 1.92 | K20: 1.39 | L20: 1.36 | M20: 1.37 | N20: 1.19 | O20: 1.2 | P20: 1.19 | Q20: 1.25 | R20: 1.22 | S20: 1.21 | T20: 1.2 | U20: 1.21 | V20: 1.23 | W20: 1.05 | X20: 1.02 | Y20: 0.99 | Z20: 1.18 | AA20: 1.15 | AB20: 1.12 | AC20: 1.34 | AD20: 1.36 | AE20: 1.33 | AF20: 1.28 | AG20: 1.27 | AH20: 1.28 | AI20: 1.37 | AJ20: 1.28 | AK20: 1.27 | AL20: 1.24 | AM20: 1.23 | AN20: 1.25 | AO20: 1.36 | AP20: 1.33 | AQ20: 1.35 | AR20: 1.2 | AS20: 1.22 | AT20: 1.21 | AU20: 1.37 | AV20: 1.34 | AW20: 1.36 | BY20: 1.49 | BZ20: 1.46 | CA20: 1.45 | CB20: 2.33 | CC20: 2.36 | CD20: 2.34
A21: 10433939 | B21: 46174 | C21: 0.7153588 | D21: 94.503 | E21: 1.89 | F21: 1.8 | G21: 1.86 | H21: 1.92 | I21: 1.9 | J21: 1.92 | K21: 1.42 | L21: 1.4 | M21: 1.4 | N21: 1.18 | O21: 1.15 | P21: 1.16 | Q21: 1.26 | R21: 1.27 | S21: 1.23 | T21: 1.17 | U21: 1.16 | V21: 1.16 | W21: 1.03 | X21: 1 | Y21: 1.04 | Z21: 1.16 | AA21: 1.13 | AB21: 1.13 | AC21: 1.36 | AD21: 1.29 | AE21: 1.32 | AF21: 1.26 | AG21: 1.23 | AH21: 1.23 | AI21: 1.37 | AJ21: 1.26 | AK21: 1.36 | AL21: 1.24 | AM21: 1.2 | AN21: 1.2 | AO21: 1.4 | AP21: 1.35 | AQ21: 1.39 | AR21: 1.19 | AS21: 1.18 | AT21: 1.18 | AU21: 1.36 | AV21: 1.35 | AW21: 1.29 | BY21: 1.51 | BZ21: 1.43 | CA21: 1.46 | CB21: 2.33 | CC21: 2.3 | CD21: 2.3
A22: 10433939 | B22: 46174 | C22: 0.71662037 | D22: 94.502 | E22: 1.9 | F22: 1.81 | G22: 1.86 | H22: 1.93 | I22: 1.9 | J22: 1.92 | K22: 1.4 | L22: 1.42 | M22: 1.42 | N22: 1.18 | O22: 1.16 | P22: 1.16 | Q22: 1.26 | R22: 1.27 | S22: 1.26 | T22: 1.17 | U22: 1.16 | V22: 1.16 | W22: 1.02 | X22: 1 | Y22: 1.03 | Z22: 1.16 | AA22: 1.13 | AB22: 1.14 | AC22: 1.34 | AD22: 1.3 | AE22: 1.32 | AF22: 1.26 | AG22: 1.23 | AH22: 1.24 | AI22: 1.36 | AJ22: 1.28 | AK22: 1.36 | AL22: 1.24 | AM22: 1.2 | AN22: 1.2 | AO22: 1.4 | AP22: 1.35 | AQ22: 1.39 | AR22: 1.19 | AS22: 1.18 | AT22: 1.16 | AU22: 1.36 | AV22: 1.35 | AW22: 1.3 | BY22: 1.51 | BZ22: 1.45 | CA22: 1.46 | CB22: 2.36 | CC22: 2.32 | CD22: 2.32
A23: 10433939 | B23: 46174 | C23: 0.73241898 | D23: 94.089 | E23: 1.86 | F23: 1.85 | G23: 1.9 | H23: 1.92 | I23: 1.9 | J23: 1.92 | K23: 1.39 | L23: 1.34 | M23: 1.34 | N23: 1.16 | O23: 1.17 | P23: 1.16 | Q23: 1.24 | R23: 1.22 | S23: 1.26 | T23: 1.17 | U23: 1.16 | V23: 1.18 | W23: 1 | X23: 0.99 | Y23: 0.99 | Z23: 1.13 | AA23: 1.1 | AB23: 1.1 | AC23: 1.32 | AD23: 1.3 | AE23: 1.36 | AF23: 1.23 | AG23: 1.22 | AH23: 1.24 | AI23: 1.21 | AJ23: 1.24 | AK23: 1.33 | AL23: 1.22 | AM23: 1.18 | AN23: 1.19 | AO23: 1.39 | AP23: 1.38 | AQ23: 1.38 | AR23: 1.18 | AS23: 1.19 | AT23: 1.19 | AU23: 1.36 | AV23: 1.39 | AW23: 1.31 | BY23: 1.51 | BZ23: 1.49 | CA23: 1.41 | CB23: 2.39 | CC23: 2.38 | CD23: 2.33
A24: 10433939 | B24: 46174 | C24: 0.73365741 | D24: 94.107 | E24: 1.85 | F24: 1.89 | G24: 1.86 | H24: 1.9 | I24: 1.92 | J24: 1.91 | K24: 1.4 | L24: 1.36 | M24: 1.37 | N24: 1.19 | O24: 1.19 | P24: 1.17 | Q24: 1.26 | R24: 1.22 | S24: 1.24 | T24: 1.19 | U24: 1.15 | V24: 1.19 | W24: 1.07 | X24: 1.03 | Y24: 1 | Z24: 1.1 | AA24: 1.12 | AB24: 1.1 | AC24: 1.36 | AD24: 1.3 | AE24: 1.34 | AF24: 1.29 | AG24: 1.26 | AH24: 1.27 | AI24: 1.26 | AJ24: 1.29 | AK24: 1.31 | AL24: 1.27 | AM24: 1.22 | AN24: 1.21 | AO24: 1.38 | AP24: 1.37 | AQ24: 1.36 | AR24: 1.19 | AS24: 1.21 | AT24: 1.2 | AU24: 1.35 | AV24: 1.36 | AW24: 1.35 | BY24: 1.5 | BZ24: 1.51 | CA24: 1.46 | CB24: 2.4 | CC24: 2.39 | CD24: 2.39
A25: 10433939 | B25: 46174 | C25: 0.73556713 | D25: 94.189 | E25: 1.9 | F25: 1.86 | G25: 1.91 | H25: 1.91 | I25: 1.93 | J25: 1.94 | K25: 1.35 | L25: 1.31 | M25: 1.32 | N25: 1.17 | O25: 1.17 | P25: 1.18 | Q25: 1.26 | R25: 1.22 | S25: 1.2 | T25: 1.18 | U25: 1.16 | V25: 1.15 | W25: 1.02 | X25: 0.94 | Y25: 0.92 | Z25: 1.12 | AA25: 1.11 | AB25: 1.13 | AC25: 1.32 | AD25: 1.31 | AE25: 1.31 | AF25: 1.24 | AG25: 1.24 | AH25: 1.25 | AI25: 1.29 | AJ25: 1.28 | AK25: 1.29 | AL25: 1.22 | AM25: 1.21 | AN25: 1.2 | AO25: 1.36 | AP25: 1.37 | AQ25: 1.3 | AR25: 1.18 | AS25: 1.17 | AT25: 1.2 | AU25: 1.39 | AV25: 1.33 | AW25: 1.29 | BY25: 1.47 | BZ25: 1.4 | CA25: 1.38 | CB25: 2.33 | CC25: 2.31 | CD25: 2.32
A26: 10433939 | B26: 46174 | C26: 0.73664352 | D26: 94.21 | E26: 1.87 | F26: 1.9 | G26: 1.9 | H26: 1.96 | I26: 1.91 | J26: 1.93 | K26: 1.32 | L26: 1.29 | M26: 1.3 | N26: 1.19 | O26: 1.16 | P26: 1.19 | Q26: 1.24 | R26: 1.26 | S26: 1.19 | T26: 1.16 | U26: 1.18 | V26: 1.17 | W26: 1.07 | X26: 1 | Y26: 0.98 | Z26: 1.16 | AA26: 1.15 | AB26: 1.1 | AC26: 1.3 | AD26: 1.28 | AE26: 1.29 | AF26: 1.24 | AG26: 1.26 | AH26: 1.21 | AI26: 1.3 | AJ26: 1.26 | AK26: 1.3 | AL26: 1.26 | AM26: 1.24 | AN26: 1.19 | AO26: 1.34 | AP26: 1.36 | AQ26: 1.29 | AR26: 1.19 | AS26: 1.2 | AT26: 1.19 | AU26: 1.36 | AV26: 1.31 | AW26: 1.3 | BY26: 1.44 | BZ26: 1.42 | CA26: 1.4 | CB26: 2.31 | CC26: 2.3 | CD26: 2.32
A27: 10433939 | B27: 46174 | C27: 0.76259259 | D27: 94.326 | E27: 1.86 | F27: 1.89 | G27: 1.92 | H27: 1.93 | I27: 1.91 | J27: 1.93 | K27: 1.36 | L27: 1.35 | M27: 1.37 | N27: 1.16 | O27: 1.18 | P27: 1.16 | Q27: 1.26 | R27: 1.21 | S27: 1.22 | T27: 1.14 | U27: 1.15 | V27: 1.15 | W27: 1.01 | X27: 0.97 | Y27: 0.97 | Z27: 1.16 | AA27: 1.11 | AB27: 1.09 | AC27: 1.34 | AD27: 1.3 | AE27: 1.31 | AF27: 1.24 | AG27: 1.25 | AH27: 1.22 | AI27: 1.31 | AJ27: 1.39 | AK27: 1.29 | AL27: 1.25 | AM27: 1.22 | AN27: 1.2 | AO27: 1.36 | AP27: 1.33 | AQ27: 1.3 | AR27: 1.15 | AS27: 1.16 | AT27: 1.16 | AU27: 1.31 | AV27: 1.39 | AW27: 1.31 | BY27: 1.46 | BZ27: 1.41 | CA27: 1.38 | CB27: 2.34 | CC27: 2.36 | CD27: 2.32
A28: 10433939 | B28: 46174 | C28: 0.7637963 | D28: 94.305 | E28: 1.89 | F28: 1.94 | G28: 1.9 | H28: 1.96 | I28: 1.9 | J28: 1.91 | K28: 1.34 | L28: 1.36 | M28: 1.34 | N28: 1.17 | O28: 1.16 | P28: 1.19 | Q28: 1.25 | R28: 1.26 | S28: 1.26 | T28: 1.2 | U28: 1.18 | V28: 1.16 | W28: 1.07 | X28: 1.03 | Y28: 1 | Z28: 1.15 | AA28: 1.14 | AB28: 1.11 | AC28: 1.36 | AD28: 1.32 | AE28: 1.3 | AF28: 1.26 | AG28: 1.29 | AH28: 1.26 | AI28: 1.29 | AJ28: 1.32 | AK28: 1.31 | AL28: 1.27 | AM28: 1.26 | AN28: 1.18 | AO28: 1.35 | AP28: 1.34 | AQ28: 1.32 | AR28: 1.19 | AS28: 1.2 | AT28: 1.19 | AU28: 1.3 | AV28: 1.36 | AW28: 1.3 | BY28: 1.47 | BZ28: 1.45 | CA28: 1.4 | CB28: 2.36 | CC28: 2.39 | CD28: 2.31
A29: 10433939 | B29: 46175 | C29: 0.66295139 | D29: 94.209 | E29: 1.86 | F29: 1.95 | G29: 1.91 | H29: 1.94 | I29: 1.93 | J29: 1.93 | K29: 1.43 | L29: 1.46 | M29: 1.42 | N29: 1.18 | O29: 1.17 | P29: 1.17 | Q29: 1.24 | R29: 1.25 | S29: 1.23 | T29: 1.18 | U29: 1.15 | V29: 1.18 | W29: 1.02 | X29: 0.97 | Y29: 1 | Z29: 1.13 | AA29: 1.1 | AB29: 1.11 | AC29: 1.36 | AD29: 1.31 | AE29: 1.3 | AF29: 1.24 | AG29: 1.23 | AH29: 1.23 | AI29: 1.28 | AJ29: 1.28 | AK29: 1.23 | AL29: 1.22 | AM29: 1.2 | AN29: 1.19 | AO29: 1.38 | AP29: 1.42 | AQ29: 1.35 | AR29: 1.16 | AS29: 1.18 | AT29: 1.19 | AU29: 1.36 | AV29: 1.36 | AW29: 1.29 | BY29: 1.48 | BZ29: 1.41 | CA29: 1.4 | CB29: 2.39 | CC29: 2.34 | CD29: 2.34
... A55: 10433939 | B55: 46178 | C55: 0.70668981 | D55: 93.986 | E55: 1.84 | F55: 1.86 | G55: 1.89 | H55: 1.93 | I55: 1.91 | J55: 1.92 | K55: 1.35 | L55: 1.37 | M55: 1.31 | N55: 1.19 | O55: 1.19 | P55: 1.18 | Q55: 1.21 | R55: 1.23 | S55: 1.2 | T55: 1.16 | U55: 1.18 | V55: 1.19 | W55: 1.03 | X55: 0.98 | Y55: 0.99 | Z55: 1.14 | AA55: 1.1 | AB55: 1.11 | AC55: 1.5 | AD55: 1.32 | AE55: 1.35 | AF55: 1.25 | AG55: 1.26 | AH55: 1.25 | AI55: 1.4 | AJ55: 1.26 | AK55: 1.32 | AL55: 1.22 | AM55: 1.21 | AN55: 1.2 | AO55: 1.36 | AP55: 1.42 | AQ55: 1.36 | AR55: 1.18 | AS55: 1.19 | AT55: 1.21 | AU55: 1.36 | AV55: 1.32 | AW55: 1.36 | BY55: 1.45 | BZ55: 1.46 | CA55: 1.44 | CB55: 2.36 | CC55: 2.39 | CD55: 2.37
A56: 10433939 | B56: 46178 | C56: 0.70793981 | D56: 93.957 | E56: 1.86 | F56: 1.85 | G56: 1.87 | H56: 1.91 | I56: 1.9 | J56: 1.96 | K56: 1.35 | L56: 1.36 | M56: 1.3 | N56: 1.2 | O56: 1.22 | P56: 1.19 | Q56: 1.22 | R56: 1.26 | S56: 1.24 | T56: 1.19 | U56: 1.21 | V56: 1.2 | W56: 1.07 | X56: 1.03 | Y56: 1 | Z56: 1.16 | AA56: 1.13 | AB56: 1.16 | AC56: 1.32 | AD56: 1.36 | AE56: 1.34 | AF56: 1.29 | AG56: 1.28 | AH56: 1.3 | AI56: 1.26 | AJ56: 1.25 | AK56: 1.26 | AL56: 1.38 | AM56: 1.4 | AN56: 1.34 | AO56: 1.19 | AP56: 1.2 | AQ56: 1.24 | AR56: 1.35 | AS56: 1.36 | AT56: 1.35 | BY56: 1.47 | BZ56: 1.45 | CA56: 1.46 | CB56: 2.38 | CC56: 2.36 | CD56: 2.35
A57: 10433939 | B57: 46178 | C57: 0.99337963 | D57: 94.92 | E57: 1.81 | F57: 1.83 | G57: 1.9 | H57: 1.94 | I57: 1.92 | J57: 1.93 | K57: 1.48 | L57: 1.46 | M57: 1.37 | N57: 1.2 | O57: 1.2 | P57: 1.17 | Q57: 1.26 | R57: 1.29 | S57: 1.2 | T57: 1.19 | U57: 1.16 | V57: 1.16 | W57: 1.03 | X57: 1 | Y57: 0.96 | Z57: 1.18 | AA57: 1.14 | AB57: 1.12 | AC57: 1.36 | AD57: 1.31 | AE57: 1.26 | AF57: 1.26 | AG57: 1.27 | AH57: 1.27 | AI57: 1.31 | AJ57: 1.3 | AK57: 1.26 | AL57: 1.23 | AM57: 1.28 | AN57: 1.2 | AO57: 1.37 | AP57: 1.37 | AQ57: 1.39 | AR57: 1.16 | AS57: 1.15 | AT57: 1.2 | AU57: 1.36 | AV57: 1.37 | AW57: 1.37 | BY57: 1.45 | BZ57: 1.46 | CA57: 1.45 | CB57: 2.35 | CC57: 2.38 | CD57: 2.36
A58: 10433939 | B58: 46178 | C58: 0.99440972 | D58: 94.926 | E58: 1.83 | F58: 1.84 | G58: 1.89 | H58: 1.93 | I58: 1.92 | J58: 1.93 | K58: 1.46 | L58: 1.47 | M58: 1.37 | N58: 1.2 | O58: 1.21 | P58: 1.19 | Q58: 1.26 | R58: 1.29 | S58: 1.2 | T58: 1.19 | U58: 1.16 | V58: 1.17 | W58: 1.03 | X58: 1 | Y58: 1 | Z58: 1.18 | AA58: 1.16 | AB58: 1.12 | AC58: 1.35 | AD58: 1.31 | AE58: 1.25 | AF58: 1.26 | AG58: 1.27 | AH58: 1.26 | AI58: 1.3 | AJ58: 1.3 | AK58: 1.26 | AL58: 1.23 | AM58: 1.26 | AN58: 1.2 | AO58: 1.36 | AP58: 1.37 | AQ58: 1.39 | AR58: 1.16 | AS58: 1.15 | AT58: 1.2 | AU58: 1.36 | AV58: 1.38 | AW58: 1.36 | BY58: 1.45 | BZ58: 1.46 | CA58: 1.45 | CB58: 2.35 | CC58: 2.39 | CD58: 2.39
A59: 10433939 | B59: 46178 | C59: 0.99555556 | D59: 94.663 | E59: 1.84 | F59: 1.91 | G59: 1.86 | H59: 1.93 | I59: 1.92 | J59: 1.94 | K59: 1.42 | L59: 1.42 | M59: 1.38 | N59: 1.17 | O59: 1.18 | P59: 1.16 | Q59: 1.29 | R59: 1.28 | S59: 1.26 | T59: 1.16 | U59: 1.17 | V59: 1.19 | W59: 1.03 | X59: 1.06 | Y59: 1 | Z59: 1.19 | AA59: 1.16 | AB59: 1.13 | AC59: 1.34 | AD59: 1.4 | AE59: 1.29 | AF59: 1.28 | AG59: 1.3 | AH59: 1.24 | AI59: 1.29 | AJ59: 1.38 | AK59: 1.21 | AL59: 1.24 | AM59: 1.24 | AN59: 1.18 | AO59: 1.29 | AP59: 1.39 | AQ59: 1.29 | AR59: 1.15 | AS59: 1.16 | AT59: 1.15 | AU59: 1.39 | AV59: 1.36 | AW59: 1.32 | BY59: 1.42 | BZ59: 1.46 | CA59: 1.39 | CB59: 2.33 | CC59: 2.35 | CD59: 2.34
A60: 10433939 | B60: 46178 | C60: 0.99671296 | D60: 94.659 | E60: 1.86 | F60: 1.92 | G60: 1.9 | H60: 1.92 | I60: 1.93 | J60: 1.94 | K60: 1.4 | L60: 1.41 | M60: 1.39 | N60: 1.16 | O60: 1.18 | P60: 1.16 | Q60: 1.29 | R60: 1.26 | S60: 1.26 | T60: 1.16 | U60: 1.17 | V60: 1.19 | W60: 1.03 | X60: 1.06 | Y60: 1 | Z60: 1.18 | AA60: 1.16 | AB60: 1.12 | AC60: 1.3 | AD60: 1.36 | AE60: 1.29 | AF60: 1.28 | AG60: 1.3 | AH60: 1.24 | AI60: 1.28 | AJ60: 1.37 | AK60: 1.26 | AL60: 1.24 | AM60: 1.26 | AN60: 1.2 | AO60: 1.28 | AP60: 1.37 | AQ60: 1.29 | AR60: 1.16 | AS60: 1.16 | AT60: 1.15 | AU60: 1.39 | AV60: 1.37 | AW60: 1.32 | BY60: 1.43 | BZ60: 1.45 | CA60: 1.4 | CB60: 2.35 | CC60: 2.38 | CD60: 2.36
A61: 10433939 | B61: 46181 | C61: 0.6896412 | D61: 94.929 | E61: 1.8 | F61: 1.86 | G61: 1.8 | H61: 1.93 | I61: 1.92 | J61: 1.93 | K61: 1.46 | L61: 1.46 | M61: 1.38 | N61: 1.16 | O61: 1.19 | P61: 1.17 | Q61: 1.29 | R61: 1.3 | S61: 1.24 | T61: 1.18 | U61: 1.16 | V61: 1.18 | W61: 1.05 | X61: 1.04 | Y61: 1.02 | Z61: 1.2 | AA61: 1.18 | AB61: 1.14 | AC61: 1.34 | AD61: 1.37 | AE61: 1.32 | AF61: 1.28 | AG61: 1.27 | AH61: 1.26 | AI61: 1.36 | AJ61: 1.33 | AK61: 1.31 | AL61: 1.26 | AM61: 1.26 | AN61: 1.23 | AO61: 1.29 | AP61: 1.32 | AQ61: 1.33 | AR61: 1.16 | AS61: 1.15 | AT61: 1.22 | AU61: 1.39 | AV61: 1.38 | AW61: 1.35 | BY61: 1.44 | BZ61: 1.44 | CA61: 1.39 | CB61: 2.33 | CC61: 2.33 | CD61: 2.33
A62: 10433939 | B62: 46181 | C62: 0.6909375 | D62: 94.926 | E62: 1.8 | F62: 1.84 | G62: 1.82 | H62: 1.92 | I62: 1.92 | J62: 1.93 | K62: 1.46 | L62: 1.46 | M62: 1.4 | N62: 1.16 | O62: 1.18 | P62: 1.16 | Q62: 1.29 | R62: 1.3 | S62: 1.26 | T62: 1.18 | U62: 1.16 | V62: 1.16 | W62: 1.05 | X62: 1.04 | Y62: 1.02 | Z62: 1.2 | AA62: 1.18 | AB62: 1.16 | AC62: 1.36 | AD62: 1.36 | AE62: 1.32 | AF62: 1.28 | AG62: 1.26 | AH62: 1.26 | AI62: 1.36 | AJ62: 1.32 | AK62: 1.31 | AL62: 1.23 | AM62: 1.26 | AN62: 1.23 | AO62: 1.29 | AP62: 1.32 | AQ62: 1.38 | AR62: 1.16 | AS62: 1.15 | AT62: 1.22 | AU62: 1.39 | AV62: 1.38 | AW62: 1.35 | BY62: 1.42 | BZ62: 1.43 | CA62: 1.4 | CB62: 2.33 | CC62: 2.34 | CD62: 2.35
